Workbook

Sheet RESUMEN 2026
D1: SOLO SERVICIO | F1: CON VENTAS EXTRAS
A2: MES 2026 | B2: $ARG/kg SERVICIO | C2: CANTIDA CABEZAS | D2: $ARG POR SERVICIO | E2: $ ARG POR CABEZA | F2: TOTAL OPERACIÓN $ARG | G2: $ARG POR ANIMAL
A3: ENERO | B3: =+AVERAGE(DETALLE!E2:E51) -> 375.8 | C3: =+DETALLE!D52 -> 1021 | D3: =+SUM(DETALLE!G2:G51) -> 84059288 | E3: =+D3/C3 -> 82330.351 | F3: =+DETALLE!I52 -> 86783487 | G3: =+F3/C3 -> 84998.518
A4: FEBRERO | B4: =+AVERAGE(DETALLE!E53:E98) -> 420 | C4: =+DETALLE!D99 -> 815 | D4: =+SUM(DETALLE!G53:G98) -> 76018824 | E4: =+D4/C4 -> 93274.631 | F4: =+DETALLE!I99 -> 80093843 | G4: =+F4/C4 -> 98274.654
A5: MARZO
A6: ABRIL
A7: MAYO
A8: JUNIO
A9: JULIO
A10: AGOSTO
A11: SEPTIEMBRE
A12: OCTUBRE
A13: NOVIEMBRE
A14: DICIEMBRE
A15: TOTAL | C15: =SUM(C3:C14) -> 1836 | D15: =SUM(D3:D14) -> 1.6007811e+08 | E15: =SUM(E3:E14) -> 175604.98 | F15: =SUM(F3:F14) -> 1.6687733e+08 | G15: =SUM(G3:G14) -> 183273.17

Sheet DETALLE
A1: MES 2026 | B1: TROPA | C1: USUARIO | D1: CANTIDAD DE ANIMALES | E1: $/kg SERVICIO S/RECUPERO | F1: KG GANCHO | G1: SERVICIO FAENA | H1: SERVICIO DESPOSTADA | I1: TOTAL OPERACIÓN $ | J1: FACTURA COMPRA MENUDENCIA | K1: FACTURA VENTA MENUDENCIA | L1: VENTA LAVADITO | M1: $ MONTO HUESO | N1: $ MONTO DESPERDICIO | O1: $ MONTO GRASA | P1: $ CUERO | Q1: $ GRASA DREASING
A2: ENERO | B2: =+'SERVICIO FAENA'!A3 -> 1 | C2: =+'SERVICIO FAENA'!B3 -> MORAGA | D2: =+'SERVICIO FAENA'!C3 -> 15 | E2: =+'SERVICIO FAENA'!H3 -> 335 | F2: =+'SERVICIO FAENA'!F3 -> 2940.3 | G2: =+'SERVICIO FAENA'!J3 -> 985000.5 | H2: =+'SERVICIO DESPOSTE'!W3 -> 0 | I2: =+(G2-J2)+K2+M2+N2+O2+P2+Q2+L2+H2 -> 985000.5 | J2: =+MENUDENCIAS!I3 -> 0 | K2: =+MENUDENCIAS!O3 -> 0 | L2: =+'MERCADO INTERNO'!AG4 -> 0 | M2: =+RENDERING!H2 -> 0 | N2: =+RENDERING!F2 -> 0 | O2: =+RENDERING!J2 -> 0 | P2: =+CUEROS!N4 -> 0 | Q2: =+'GRASA DREASING'!G2 -> 0
B3: =+'SERVICIO FAENA'!A4 -> 2 | C3: =+'SERVICIO FAENA'!B4 -> GANADERA NORTE NEUQUINO | D3: =+'SERVICIO FAENA'!C4 -> 43 | E3: =+'SERVICIO FAENA'!H4 -> 335 | F3: =+'SERVICIO FAENA'!F4 -> 9891.8 | G3: =+'SERVICIO FAENA'!J4 -> 3313753 | H3: =+'SERVICIO DESPOSTE'!W4 -> 0 | I3: =+(G3-J3)+K3+M3+N3+O3+P3+Q3+L3+H3 -> 3313753 | J3: =+MENUDENCIAS!I4 -> 0 | K3: =+MENUDENCIAS!O4 -> 0 | L3: =+'MERCADO INTERNO'!AG5 -> 0 | M3: =+RENDERING!H3 -> 0 | N3: =+RENDERING!F3 -> 0 | O3: =+RENDERING!J3 -> 0 | P3: =+CUEROS!N5 -> 0 | Q3: =+'GRASA DREASING'!G3 -> 0
B4: =+'SERVICIO FAENA'!A5 -> 3 | C4: =+'SERVICIO FAENA'!B5 -> GANADERA NORTE NEUQUINO | D4: =+'SERVICIO FAENA'!C5 -> 40 | E4: =+'SERVICIO FAENA'!H5 -> 335 | F4: =+'SERVICIO FAENA'!F5 -> 8567.8 | G4: =+'SERVICIO FAENA'!J5 -> 2870213 | H4: =+'SERVICIO DESPOSTE'!W5 -> 0 | I4: =+(G4-J4)+K4+M4+N4+O4+P4+Q4+L4+H4 -> 2870213 | J4: =+MENUDENCIAS!I5 -> 0 | K4: =+MENUDENCIAS!O5 -> 0 | L4: =+'MERCADO INTERNO'!AG6 -> 0 | M4: =+RENDERING!H4 -> 0 | N4: =+RENDERING!F4 -> 0 | O4: =+RENDERING!J4 -> 0 | P4: =+CUEROS!N6 -> 0 | Q4: =+'GRASA DREASING'!G4 -> 0
B5: =+'SERVICIO FAENA'!A6 -> 4 | C5: =+'SERVICIO FAENA'!B6 -> DOS DE FIERRO SA | D5: =+'SERVICIO FAENA'!C6 -> 25 | E5: =+'SERVICIO FAENA'!H6 -> 335 | F5: =+'SERVICIO FAENA'!F6 -> 5030.4 | G5: =+'SERVICIO FAENA'!J6 -> 1685184 | H5: =+'SERVICIO DESPOSTE'!W6 -> 0 | I5: =+(G5-J5)+K5+M5+N5+O5+P5+Q5+L5+H5 -> 1685184 | J5: =+MENUDENCIAS!I6 -> 0 | K5: =+MENUDENCIAS!O6 -> 0 | L5: =+'MERCADO INTERNO'!AG7 -> 0 | M5: =+RENDERING!H5 -> 0 | N5: =+RENDERING!F5 -> 0 | O5: =+RENDERING!J5 -> 0 | P5: =+CUEROS!N7 -> 0 | Q5: =+'GRASA DREASING'!G5 -> 0
B6: =+'SERVICIO FAENA'!A7 -> 5 | C6: =+'SERVICIO FAENA'!B7 -> DISTRIBUIDORA DE LA PATAGONIA | D6: =+'SERVICIO FAENA'!C7 -> 30 | E6: =+'SERVICIO FAENA'!H7 -> 335 | F6: =+'SERVICIO FAENA'!F7 -> 6743.3 | G6: =+'SERVICIO FAENA'!J7 -> 2259005.5 | H6: =+'SERVICIO DESPOSTE'!W7 -> 0 | I6: =+(G6-J6)+K6+M6+N6+O6+P6+Q6+L6+H6 -> 2259005.5 | J6: =+MENUDENCIAS!I7 -> 0 | K6: =+MENUDENCIAS!O7 -> 0 | L6: =+'MERCADO INTERNO'!AG8 -> 0 | M6: =+RENDERING!H6 -> 0 | N6: =+RENDERING!F6 -> 0 | O6: =+RENDERING!J6 -> 0 | P6: =+CUEROS!N8 -> 0 | Q6: =+'GRASA DREASING'!G6 -> 0
B7: =+'SERVICIO FAENA'!A8 -> 6 | C7: =+'SERVICIO FAENA'!B8 -> DISTRIBUIDORA DE LA PATAGONIA | D7: =+'SERVICIO FAENA'!C8 -> 15 | E7: =+'SERVICIO FAENA'!H8 -> 335 | F7: =+'SERVICIO FAENA'!F8 -> 3075.2 | G7: =+'SERVICIO FAENA'!J8 -> 1030192 | H7: =+'SERVICIO DESPOSTE'!W8 -> 0 | I7: =+(G7-J7)+K7+M7+N7+O7+P7+Q7+L7+H7 -> 1030192 | J7: =+MENUDENCIAS!I8 -> 0 | K7: =+MENUDENCIAS!O8 -> 0 | L7: =+'MERCADO INTERNO'!AG9 -> 0 | M7: =+RENDERING!H7 -> 0 | N7: =+RENDERING!F7 -> 0 | O7: =+RENDERING!J7 -> 0 | P7: =+CUEROS!N9 -> 0 | Q7: =+'GRASA DREASING'!G7 -> 0
B8: =+'SERVICIO FAENA'!A9 -> 7 | C8: =+'SERVICIO FAENA'!B9 -> MUCA SAS | D8: =+'SERVICIO FAENA'!C9 -> 35 | E8: =+'SERVICIO FAENA'!H9 -> 335 | F8: =+'SERVICIO FAENA'!F9 -> 10641.5 | G8: =+'SERVICIO FAENA'!J9 -> 3564902.5 | H8: =+'SERVICIO DESPOSTE'!W9 -> 0 | I8: =+(G8-J8)+K8+M8+N8+O8+P8+Q8+L8+H8 -> 3564902.5 | J8: =+MENUDENCIAS!I9 -> 0 | K8: =+MENUDENCIAS!O9 -> 0 | L8: =+'MERCADO INTERNO'!AG10 -> 0 | M8: =+RENDERING!H8 -> 0 | N8: =+RENDERING!F8 -> 0 | O8: =+RENDERING!J8 -> 0 | P8: =+CUEROS!N10 -> 0 | Q8: =+'GRASA DREASING'!G8 -> 0
B9: =+'SERVICIO FAENA'!A10 -> 8 | C9: =+'SERVICIO FAENA'!B10 -> MUCA SAS | D9: =+'SERVICIO FAENA'!C10 -> 5 | E9: =+'SERVICIO FAENA'!H10 -> 335 | F9: =+'SERVICIO FAENA'!F10 -> 1585.2 | G9: =+'SERVICIO FAENA'!J10 -> 531042 | H9: =+'SERVICIO DESPOSTE'!W10 -> 0 | I9: =+(G9-J9)+K9+M9+N9+O9+P9+Q9+L9+H9 -> 531042 | J9: =+MENUDENCIAS!I10 -> 0 | K9: =+MENUDENCIAS!O10 -> 0 | L9: =+'MERCADO INTERNO'!AG11 -> 0 | M9: =+RENDERING!H9 -> 0 | N9: =+RENDERING!F9 -> 0 | O9: =+RENDERING!J9 -> 0 | P9: =+CUEROS!N11 -> 0 | Q9: =+'GRASA DREASING'!G9 -> 0
B10: =+'SERVICIO FAENA'!A11 -> 9 | C10: =+'SERVICIO FAENA'!B11 -> MUCA SAS | D10: =+'SERVICIO FAENA'!C11 -> 10 | E10: =+'SERVICIO FAENA'!H11 -> 335 | F10: =+'SERVICIO FAENA'!F11 -> 2712.6 | G10: =+'SERVICIO FAENA'!J11 -> 908721 | H10: =+'SERVICIO DESPOSTE'!W11 -> 0 | I10: =+(G10-J10)+K10+M10+N10+O10+P10+Q10+L10+H10 -> 908721 | J10: =+MENUDENCIAS!I11 -> 0 | K10: =+MENUDENCIAS!O11 -> 0 | L10: =+'MERCADO INTERNO'!AG12 -> 0 | M10: =+RENDERING!H10 -> 0 | N10: =+RENDERING!F10 -> 0 | O10: =+RENDERING!J10 -> 0 | P10: =+CUEROS!N12 -> 0 | Q10: =+'GRASA DREASING'!G10 -> 0
B11: =+'SERVICIO FAENA'!A12 -> 10 | C11: =+'SERVICIO FAENA'!B12 -> MORAGA | D11: =+'SERVICIO FAENA'!C12 -> 15 | E11: =+'SERVICIO FAENA'!H12 -> 335 | F11: =+'SERVICIO FAENA'!F12 -> 3623.5 | G11: =+'SERVICIO FAENA'!J12 -> 1213872.5 | H11: =+'SERVICIO DESPOSTE'!W12 -> 0 | I11: =+(G11-J11)+K11+M11+N11+O11+P11+Q11+L11+H11 -> 1213872.5 | J11: =+MENUDENCIAS!I12 -> 0 | K11: =+MENUDENCIAS!O12 -> 0 | L11: =+'MERCADO INTERNO'!AG13 -> 0 | M11: =+RENDERING!H11 -> 0 | N11: =+RENDERING!F11 -> 0 | O11: =+RENDERING!J11 -> 0 | P11: =+CUEROS!N13 -> 0 | Q11: =+'GRASA DREASING'!G11 -> 0
B12: =+'SERVICIO FAENA'!A13 -> 11 | C12: =+'SERVICIO FAENA'!B13 -> FERREYRA MARTIN | D12: =+'SERVICIO FAENA'!C13 -> 20 | E12: =+'SERVICIO FAENA'!H13 -> 335 | F12: =+'SERVICIO FAENA'!F13 -> 3381.6 | G12: =+'SERVICIO FAENA'!J13 -> 1132836 | H12: =+'SERVICIO DESPOSTE'!W13 -> 0 | I12: =+(G12-J12)+K12+M12+N12+O12+P12+Q12+L12+H12 -> 1132836 | J12: =+MENUDENCIAS!I13 -> 0 | K12: =+MENUDENCIAS!O13 -> 0 | L12: =+'MERCADO INTERNO'!AG14 -> 0 | M12: =+RENDERING!H12 -> 0 | N12: =+RENDERING!F12 -> 0 | O12: =+RENDERING!J12 -> 0 | P12: =+CUEROS!N14 -> 0 | Q12: =+'GRASA DREASING'!G12 -> 0
B13: =+'SERVICIO FAENA'!A14 -> 12 | C13: =+'SERVICIO FAENA'!B14 -> FERREYRA MARTIN | D13: =+'SERVICIO FAENA'!C14 -> 3 | E13: =+'SERVICIO FAENA'!H14 -> 335 | F13: =+'SERVICIO FAENA'!F14 -> 467.9 | G13: =+'SERVICIO FAENA'!J14 -> 156746.5 | H13: =+'SERVICIO DESPOSTE'!W14 -> 0 | I13: =+(G13-J13)+K13+M13+N13+O13+P13+Q13+L13+H13 -> 409253.22 | J13: =+MENUDENCIAS!I14 -> 0 | K13: =+MENUDENCIAS!O14 -> 0 | L13: =+'MERCADO INTERNO'!AG15 -> 252506.72 | M13: =+RENDERING!H13 -> 0 | N13: =+RENDERING!F13 -> 0 | O13: =+RENDERING!J13 -> 0 | P13: =+CUEROS!N15 -> 0 | Q13: =+'GRASA DREASING'!G13 -> 0
B14: =+'SERVICIO FAENA'!A15 -> 13 | C14: =+'SERVICIO FAENA'!B15 -> GANADERA NORTE NEUQUINO | D14: =+'SERVICIO FAENA'!C15 -> 40 | E14: =+'SERVICIO FAENA'!H15 -> 335 | F14: =+'SERVICIO FAENA'!F15 -> 8946.1 | G14: =+'SERVICIO FAENA'!J15 -> 2996943.5 | H14: =+'SERVICIO DESPOSTE'!W15 -> 0 | I14: =+(G14-J14)+K14+M14+N14+O14+P14+Q14+L14+H14 -> 3253567.9 | J14: =+MENUDENCIAS!I15 -> 0 | K14: =+MENUDENCIAS!O15 -> 0 | L14: =+'MERCADO INTERNO'!AG16 -> 256624.45 | M14: =+RENDERING!H14 -> 0 | N14: =+RENDERING!F14 -> 0 | O14: =+RENDERING!J14 -> 0 | P14: =+CUEROS!N16 -> 0 | Q14: =+'GRASA DREASING'!G14 -> 0
... B51: =+'SERVICIO FAENA'!A52 -> 50 | C51: =+'SERVICIO FAENA'!B52 -> MUCA SAS | D51: =+'SERVICIO FAENA'!C52 -> 2 | E51: =+'SERVICIO FAENA'!H52 -> 420 | F51: =+'SERVICIO FAENA'!F52 -> 423.7 | G51: =+'SERVICIO FAENA'!J52 -> 177954 | H51: =+'SERVICIO DESPOSTE'!W52 -> 0 | I51: =+(G51-J51)+K51+M51+N51+O51+P51+Q51+L51+H51 -> 177954 | J51: =+MENUDENCIAS!I52 -> 0 | K51: =+MENUDENCIAS!O52 -> 0 | L51: =+'MERCADO INTERNO'!AG53 -> 0 | M51: =+RENDERING!H51 -> 0 | N51: =+RENDERING!F51 -> 0 | O51: =+RENDERING!J51 -> 0 | P51: =+CUEROS!N53 -> 0 | Q51: =+'GRASA DREASING'!G51 -> 0
A52: TOTAL | D52: =SUM(D2:D51) -> 1021 | F52: Promedio animal | G52: =+I52/D52 -> 84998.518 | I52: =SUM(I2:I51) -> 86783487
A53: FEBRERO | B53: =+'SERVICIO FAENA'!A53 -> 51 | C53: =+'SERVICIO FAENA'!B53 -> GANADERA NORTE NEUQUINO | D53: =+'SERVICIO FAENA'!C53 -> 42 | E53: =+'SERVICIO FAENA'!H53 -> 420 | F53: =+'SERVICIO FAENA'!F53 -> 9646.8 | G53: =+'SERVICIO FAENA'!J53 -> 4051656 | H53: =+'SERVICIO DESPOSTE'!W53 -> 0 | I53: =+(G53-J53)+K53+M53+N53+O53+P53+Q53+L53+H53 -> 4188456 | J53: =+MENUDENCIAS!I53 -> 0 | K53: =+MENUDENCIAS!O53 -> 0 | L53: =+'MERCADO INTERNO'!AG54 -> 0 | M53: =+RENDERING!H52 -> 36000 | N53: =+RENDERING!F52 -> 81600 | O53: =+RENDERING!J52 -> 19200 | P53: =+CUEROS!N55 -> 0 | Q53: =+'GRASA DREASING'!G52 -> 0
B54: =+'SERVICIO FAENA'!A54 -> 52 | C54: =+'SERVICIO FAENA'!B54 -> FERREYRA MARTIN | D54: =+'SERVICIO FAENA'!C54 -> 18 | E54: =+'SERVICIO FAENA'!H54 -> 420 | F54: =+'SERVICIO FAENA'!F54 -> 3004.4 | G54: =+'SERVICIO FAENA'!J54 -> 1261848 | H54: =+'SERVICIO DESPOSTE'!W54 -> 0 | I54: =+(G54-J54)+K54+M54+N54+O54+P54+Q54+L54+H54 -> 1261848 | J54: =+MENUDENCIAS!I54 -> 0 | K54: =+MENUDENCIAS!O54 -> 0 | L54: =+'MERCADO INTERNO'!AG55 -> 0 | M54: =+RENDERING!H53 -> 0 | N54: =+RENDERING!F53 -> 0 | O54: =+RENDERING!J53 -> 0 | P54: =+CUEROS!N56 -> 0 | Q54: =+'GRASA DREASING'!G53 -> 0
B55: =+'SERVICIO FAENA'!A55 -> 53 | C55: =+'SERVICIO FAENA'!B55 -> BOSQUES AMADOS SRL | D55: =+'SERVICIO FAENA'!C55 -> 17 | E55: =+'SERVICIO FAENA'!H55 -> 420 | F55: =+'SERVICIO FAENA'!F55 -> 3545.7 | G55: =+'SERVICIO FAENA'!J55 -> 1489194 | H55: =+'SERVICIO DESPOSTE'!W55 -> 0 | I55: =+(G55-J55)+K55+M55+N55+O55+P55+Q55+L55+H55 -> 1489194 | J55: =+MENUDENCIAS!I55 -> 0 | K55: =+MENUDENCIAS!O55 -> 0 | L55: =+'MERCADO INTERNO'!AG56 -> 0 | M55: =+RENDERING!H54 -> 0 | N55: =+RENDERING!F54 -> 0 | O55: =+RENDERING!J54 -> 0 | P55: =+CUEROS!N57 -> 0 | Q55: =+'GRASA DREASING'!G54 -> 0
B56: =+'SERVICIO FAENA'!A56 -> 54 | C56: =+'SERVICIO FAENA'!B56 -> MUCA SAS | D56: =+'SERVICIO FAENA'!C56 -> 50 | E56: =+'SERVICIO FAENA'!H56 -> 420 | F56: =+'SERVICIO FAENA'!F56 -> 15684.1 | G56: =+'SERVICIO FAENA'!J56 -> 6587322 | H56: =+'SERVICIO DESPOSTE'!W56 -> 0 | I56: =+(G56-J56)+K56+M56+N56+O56+P56+Q56+L56+H56 -> 6770522 | J56: =+MENUDENCIAS!I56 -> 0 | K56: =+MENUDENCIAS!O56 -> 0 | L56: =+'MERCADO INTERNO'!AG57 -> 0 | M56: =+RENDERING!H55 -> 36000 | N56: =+RENDERING!F55 -> 111200 | O56: =+RENDERING!J55 -> 36000 | P56: =+CUEROS!N58 -> 0 | Q56: =+'GRASA DREASING'!G55 -> 0
B57: =+'SERVICIO FAENA'!A57 -> 55 | C57: =+'SERVICIO FAENA'!B57 -> MORAGA | D57: =+'SERVICIO FAENA'!C57 -> 10 | E57: =+'SERVICIO FAENA'!H57 -> 420 | F57: =+'SERVICIO FAENA'!F57 -> 1943.7 | G57: =+'SERVICIO FAENA'!J57 -> 816354 | H57: =+'SERVICIO DESPOSTE'!W57 -> 0 | I57: =+(G57-J57)+K57+M57+N57+O57+P57+Q57+L57+H57 -> 889154 | J57: =+MENUDENCIAS!I57 -> 0 | K57: =+MENUDENCIAS!O57 -> 0 | L57: =+'MERCADO INTERNO'!AG58 -> 0 | M57: =+RENDERING!H56 -> 19200 | N57: =+RENDERING!F56 -> 42400 | O57: =+RENDERING!J56 -> 11200 | P57: =+CUEROS!N59 -> 0 | Q57: =+'GRASA DREASING'!G56 -> 0
B58: =+'SERVICIO FAENA'!A58 -> 56 | C58: =+'SERVICIO FAENA'!B58 -> FERREYRA MARTIN | D58: =+'SERVICIO FAENA'!C58 -> 15 | E58: =+'SERVICIO FAENA'!H58 -> 420 | F58: =+'SERVICIO FAENA'!F58 -> 3484.6 | G58: =+'SERVICIO FAENA'!J58 -> 1463532 | H58: =+'SERVICIO DESPOSTE'!W58 -> 0 | I58: =+(G58-J58)+K58+M58+N58+O58+P58+Q58+L58+H58 -> 1463532 | J58: =+MENUDENCIAS!I58 -> 0 | K58: =+MENUDENCIAS!O58 -> 0 | L58: =+'MERCADO INTERNO'!AG59 -> 0 | M58: =+RENDERING!H57 -> 0 | N58: =+RENDERING!F57 -> 0 | O58: =+RENDERING!J57 -> 0 | P58: =+CUEROS!N60 -> 0 | Q58: =+'GRASA DREASING'!G57 -> 0
B59: =+'SERVICIO FAENA'!A59 -> 57 | C59: =+'SERVICIO FAENA'!B59 -> FERREYRA ALBERTO | D59: =+'SERVICIO FAENA'!C59 -> 5 | E59: =+'SERVICIO FAENA'!H59 -> 420 | F59: =+'SERVICIO FAENA'!F59 -> 925.9 | G59: =+'SERVICIO FAENA'!J59 -> 388878 | H59: =+'SERVICIO DESPOSTE'!W59 -> 0 | I59: =+(G59-J59)+K59+M59+N59+O59+P59+Q59+L59+H59 -> 388878 | J59: =+MENUDENCIAS!I59 -> 0 | K59: =+MENUDENCIAS!O59 -> 0 | L59: =+'MERCADO INTERNO'!AG60 -> 0 | M59: =+RENDERING!H58 -> 0 | N59: =+RENDERING!F58 -> 0 | O59: =+RENDERING!J58 -> 0 | P59: =+CUEROS!N61 -> 0 | Q59: =+'GRASA DREASING'!G58 -> 0
B60: =+'SERVICIO FAENA'!A60 -> 58 | C60: =+'SERVICIO FAENA'!B60 -> FERREYRA MARTIN | D60: =+'SERVICIO FAENA'!C60 -> 10 | E60: =+'SERVICIO FAENA'!H60 -> 420 | F60: =+'SERVICIO FAENA'!F60 -> 1768.6 | G60: =+'SERVICIO FAENA'!J60 -> 742812 | H60: =+'SERVICIO DESPOSTE'!W60 -> 0 | I60: =+(G60-J60)+K60+M60+N60+O60+P60+Q60+L60+H60 -> 742812 | J60: =+MENUDENCIAS!I60 -> 0 | K60: =+MENUDENCIAS!O60 -> 0 | L60: =+'MERCADO INTERNO'!AG61 -> 0 | M60: =+RENDERING!H59 -> 0 | N60: =+RENDERING!F59 -> 0 | O60: =+RENDERING!J59 -> 0 | P60: =+CUEROS!N62 -> 0 | Q60: =+'GRASA DREASING'!G59 -> 0
B61: =+'SERVICIO FAENA'!A61 -> 59 | C61: =+'SERVICIO FAENA'!B61 -> FRIGORIFICO DE LA PATAGONIA SRL | D61: =+'SERVICIO FAENA'!C61 -> 20 | E61: =+'SERVICIO FAENA'!H61 -> 420 | F61: =+'SERVICIO FAENA'!F61 -> 3150.7 | G61: =+'SERVICIO FAENA'!J61 -> 1323294 | H61: =+'SERVICIO DESPOSTE'!W61 -> 0 | I61: =+(G61-J61)+K61+M61+N61+O61+P61+Q61+L61+H61 -> 1463294 | J61: =+MENUDENCIAS!I61 -> 0 | K61: =+MENUDENCIAS!O61 -> 0 | L61: =+'MERCADO INTERNO'!AG62 -> 0 | M61: =+RENDERING!H60 -> 39200 | N61: =+RENDERING!F60 -> 83200 | O61: =+RENDERING!J60 -> 17600 | P61: =+CUEROS!N63 -> 0 | Q61: =+'GRASA DREASING'!G60 -> 0
B62: =+'SERVICIO FAENA'!A62 -> 60 | C62: =+'SERVICIO FAENA'!B62 -> FRIGORIFICO DE LA PATAGONIA SRL | D62: =+'SERVICIO FAENA'!C62 -> 28 | E62: =+'SERVICIO FAENA'!H62 -> 420 | F62: =+'SERVICIO FAENA'!F62 -> 5073.9 | G62: =+'SERVICIO FAENA'!J62 -> 2131038 | H62: =+'SERVICIO DESPOSTE'!W62 -> 0 | I62: =+(G62-J62)+K62+M62+N62+O62+P62+Q62+L62+H62 -> 2131038 | J62: =+MENUDENCIAS!I62 -> 0 | K62: =+MENUDENCIAS!O62 -> 0 | L62: =+'MERCADO INTERNO'!AG63 -> 0 | M62: =+RENDERING!H61 -> 0 | N62: =+RENDERING!F61 -> 0 | O62: =+RENDERING!J61 -> 0 | P62: =+CUEROS!N64 -> 0 | Q62: =+'GRASA DREASING'!G61 -> 0
B63: =+'SERVICIO FAENA'!A63 -> 61 | C63: =+'SERVICIO FAENA'!B63 -> MAIZALES DE LA PATAGONIA SRL | D63: =+'SERVICIO FAENA'!C63 -> 20 | E63: =+'SERVICIO FAENA'!H63 -> 420 | F63: =+'SERVICIO FAENA'!F63 -> 4074.2 | G63: =+'SERVICIO FAENA'!J63 -> 1711164 | H63: =+'SERVICIO DESPOSTE'!W63 -> 0 | I63: =+(G63-J63)+K63+M63+N63+O63+P63+Q63+L63+H63 -> 1711164 | J63: =+MENUDENCIAS!I63 -> 0 | K63: =+MENUDENCIAS!O63 -> 0 | L63: =+'MERCADO INTERNO'!AG64 -> 0 | M63: =+RENDERING!H62 -> 0 | N63: =+RENDERING!F62 -> 0 | O63: =+RENDERING!J62 -> 0 | P63: =+CUEROS!N65 -> 0 | Q63: =+'GRASA DREASING'!G62 -> 0
B64: =+'SERVICIO FAENA'!A64 -> 62 | C64: =+'SERVICIO FAENA'!B64 -> FRIGORIFICO DE LA PATAGONIA SRL | D64: =+'SERVICIO FAENA'!C64 -> 1 | E64: =+'SERVICIO FAENA'!H64 -> 420 | F64: =+'SERVICIO FAENA'!F64 -> 189.7 | G64: =+'SERVICIO FAENA'!J64 -> 79674 | H64: =+'SERVICIO DESPOSTE'!W64 -> 0 | I64: =+(G64-J64)+K64+M64+N64+O64+P64+Q64+L64+H64 -> 79674 | J64: =+MENUDENCIAS!I64 -> 0 | K64: =+MENUDENCIAS!O64 -> 0 | L64: =+'MERCADO INTERNO'!AG65 -> 0 | M64: =+RENDERING!H63 -> 0 | N64: =+RENDERING!F63 -> 0 | O64: =+RENDERING!J63 -> 0 | P64: =+CUEROS!N66 -> 0 | Q64: =+'GRASA DREASING'!G63 -> 0
B65: =+'SERVICIO FAENA'!A65 -> 63 | C65: =+'SERVICIO FAENA'!B65 -> FERREYRA MARTIN | D65: =+'SERVICIO FAENA'!C65 -> 8 | E65: =+'SERVICIO FAENA'!H65 -> 420 | F65: =+'SERVICIO FAENA'!F65 -> 1437.3 | G65: =+'SERVICIO FAENA'!J65 -> 603666 | H65: =+'SERVICIO DESPOSTE'!W65 -> 0 | I65: =+(G65-J65)+K65+M65+N65+O65+P65+Q65+L65+H65 -> 761266 | J65: =+MENUDENCIAS!I65 -> 0 | K65: =+MENUDENCIAS!O65 -> 0 | L65: =+'MERCADO INTERNO'!AG66 -> 0 | M65: =+RENDERING!H64 -> 45600 | N65: =+RENDERING!F64 -> 84000 | O65: =+RENDERING!J64 -> 28000 | P65: =+CUEROS!N67 -> 0 | Q65: =+'GRASA DREASING'!G64 -> 0
... B98: =+'SERVICIO FAENA'!A98 -> 96 | C98: =+'SERVICIO FAENA'!B98 -> FRIGORIFICO DE LA PATAGONIA SRL | D98: =+'SERVICIO FAENA'!C98 -> 22 | E98: =+'SERVICIO FAENA'!H98 -> 420 | F98: =+'SERVICIO FAENA'!F98 -> 4885.3 | G98: =+'SERVICIO FAENA'!J98 -> 2051826 | H98: =+'SERVICIO DESPOSTE'!W98 -> 0 | I98: =+(G98-J98)+K98+M98+N98+O98+P98+Q98+L98+H98 -> 2051826 | J98: =+MENUDENCIAS!I98 -> 0 | K98: =+MENUDENCIAS!O98 -> 0 | L98: =+'MERCADO INTERNO'!AG99 -> 0 | M98: =+RENDERING!H97 -> 0 | N98: =+RENDERING!F97 -> 0 | O98: =+RENDERING!J97 -> 0 | P98: =+CUEROS!N100 -> 0 | Q98: =+'GRASA DREASING'!G97 -> 0
A99: TOTAL | D99: =SUM(D53:D98) -> 815 | F99: Promedio animal | G99: =+I99/D99 -> 98274.654 | I99: =SUM(I53:I98) -> 80093843
A100: MARZO | B100: =+'SERVICIO FAENA'!A99 -> 97 | C100: =+'SERVICIO FAENA'!B99 -> FERREYRA MARTIN | D100: =+'SERVICIO FAENA'!C99 -> 18 | E100: =+'SERVICIO FAENA'!H99 -> 500 | F100: =+'SERVICIO FAENA'!F99 -> 2665.6 | G100: =+'SERVICIO FAENA'!J99 -> 1332800 | H100: =+'SERVICIO DESPOSTE'!W99 -> 0 | I100: =+(G100-J100)+K100+M100+N100+O100+P100+Q100+L100+H100 -> 1332800 | J100: =+MENUDENCIAS!I99 -> 0 | K100: =+MENUDENCIAS!O99 -> 0 | L100: =+MENUDENCIAS!P99 -> 0 | M100: =+RENDERING!H98 -> 0 | N100: =+RENDERING!F98 -> 0 | O100: =+RENDERING!J98 -> 0 | P100: =+CUEROS!N101 -> 0 | Q100: =+'GRASA DREASING'!G98 -> 0
B101: =+'SERVICIO FAENA'!A100 -> 98 | C101: =+'SERVICIO FAENA'!B100 -> GANADERA NORTE NEUQUINO | D101: =+'SERVICIO FAENA'!C100 -> 44 | E101: =+'SERVICIO FAENA'!H100 -> 500 | F101: =+'SERVICIO FAENA'!F100 -> 9281.5 | G101: =+'SERVICIO FAENA'!J100 -> 4640750 | H101: =+'SERVICIO DESPOSTE'!W100 -> 0 | I101: =+(G101-J101)+K101+M101+N101+O101+P101+Q101+L101+H101 -> 4640750 | J101: =+MENUDENCIAS!I100 -> 0 | K101: =+MENUDENCIAS!O100 -> 0 | L101: =+MENUDENCIAS!P100 -> 0 | M101: =+RENDERING!H99 -> 0 | N101: =+RENDERING!F99 -> 0 | O101: =+RENDERING!J99 -> 0 | P101: =+CUEROS!N102 -> 0 | Q101: =+'GRASA DREASING'!G99 -> 0
B102: =+'SERVICIO FAENA'!A101 -> 99 | C102: =+'SERVICIO FAENA'!B101 -> DOS DE FIERRO SA | D102: =+'SERVICIO FAENA'!C101 -> 21 | E102: =+'SERVICIO FAENA'!H101 -> 500 | F102: =+'SERVICIO FAENA'!F101 -> 4772.3 | G102: =+'SERVICIO FAENA'!J101 -> 2386150 | H102: =+'SERVICIO DESPOSTE'!W101 -> 0 | I102: =+(G102-J102)+K102+M102+N102+O102+P102+Q102+L102+H102 -> 2386150 | J102: =+MENUDENCIAS!I101 -> 0 | K102: =+MENUDENCIAS!O101 -> 0 | L102: =+MENUDENCIAS!P101 -> 0 | M102: =+RENDERING!H100 -> 0 | N102: =+RENDERING!F100 -> 0 | O102: =+RENDERING!J100 -> 0 | P102: =+CUEROS!N103 -> 0 | Q102: =+'GRASA DREASING'!G100 -> 0
B103: =+'SERVICIO FAENA'!A102 -> 100 | C103: =+'SERVICIO FAENA'!B102 -> BOSQUES AMADOS SRL | D103: =+'SERVICIO FAENA'!C102 -> 18 | E103: =+'SERVICIO FAENA'!H102 -> 500 | F103: =+'SERVICIO FAENA'!F102 -> 3494.7 | G103: =+'SERVICIO FAENA'!J102 -> 1747350 | H103: =+'SERVICIO DESPOSTE'!W102 -> 0 | I103: =+(G103-J103)+K103+M103+N103+O103+P103+Q103+L103+H103 -> 1747350 | J103: =+MENUDENCIAS!I102 -> 0 | K103: =+MENUDENCIAS!O102 -> 0 | L103: =+MENUDENCIAS!P102 -> 0 | M103: =+RENDERING!H101 -> 0 | N103: =+RENDERING!F101 -> 0 | O103: =+RENDERING!J101 -> 0 | P103: =+CUEROS!N104 -> 0 | Q103: =+'GRASA DREASING'!G101 -> 0
B104: =+'SERVICIO FAENA'!A103 -> 101 | C104: =+'SERVICIO FAENA'!B103 -> FERREYRA ALBERTO | D104: =+'SERVICIO FAENA'!C103 -> 8 | E104: =+'SERVICIO FAENA'!H103 -> 500 | F104: =+'SERVICIO FAENA'!F103 -> 1416.4 | G104: =+'SERVICIO FAENA'!J103 -> 708200 | H104: =+'SERVICIO DESPOSTE'!W103 -> 0 | I104: =+(G104-J104)+K104+M104+N104+O104+P104+Q104+L104+H104 -> 708200 | J104: =+MENUDENCIAS!I103 -> 0 | K104: =+MENUDENCIAS!O103 -> 0 | L104: =+MENUDENCIAS!P103 -> 0 | M104: =+RENDERING!H102 -> 0 | N104: =+RENDERING!F102 -> 0 | O104: =+RENDERING!J102 -> 0 | P104: =+CUEROS!N105 -> 0 | Q104: =+'GRASA DREASING'!G102 -> 0
B105: =+'SERVICIO FAENA'!A104 -> 102 | C105: =+'SERVICIO FAENA'!B104 -> FERREYRA MARTIN | D105: =+'SERVICIO FAENA'!C104 -> 12 | E105: =+'SERVICIO FAENA'!H104 -> 500 | F105: =+'SERVICIO FAENA'!F104 -> 2884.7 | G105: =+'SERVICIO FAENA'!J104 -> 1442350 | H105: =+'SERVICIO DESPOSTE'!W104 -> 0 | I105: =+(G105-J105)+K105+M105+N105+O105+P105+Q105+L105+H105 -> 1442350 | J105: =+MENUDENCIAS!I104 -> 0 | K105: =+MENUDENCIAS!O104 -> 0 | L105: =+MENUDENCIAS!P104 -> 0 | M105: =+RENDERING!H103 -> 0 | N105: =+RENDERING!F103 -> 0 | O105: =+RENDERING!J103 -> 0 | P105: =+CUEROS!N106 -> 0 | Q105: =+'GRASA DREASING'!G103 -> 0
B106: =+'SERVICIO FAENA'!A105 -> 103 | C106: =+'SERVICIO FAENA'!B105 -> FERREYRA MARTIN | D106: =+'SERVICIO FAENA'!C105 -> 10 | E106: =+'SERVICIO FAENA'!H105 -> 500 | F106: =+'SERVICIO FAENA'!F105 -> 1674.7 | G106: =+'SERVICIO FAENA'!J105 -> 837350 | H106: =+'SERVICIO DESPOSTE'!W105 -> 0 | I106: =+(G106-J106)+K106+M106+N106+O106+P106+Q106+L106+H106 -> 837350 | J106: =+MENUDENCIAS!I105 -> 0 | K106: =+MENUDENCIAS!O105 -> 0 | L106: =+MENUDENCIAS!P105 -> 0 | M106: =+RENDERING!H104 -> 0 | N106: =+RENDERING!F104 -> 0 | O106: =+RENDERING!J104 -> 0 | P106: =+CUEROS!N107 -> 0 | Q106: =+'GRASA DREASING'!G104 -> 0
B107: =+'SERVICIO FAENA'!A106 -> 104 | C107: =+'SERVICIO FAENA'!B106 -> MUCA SAS | D107: =+'SERVICIO FAENA'!C106 -> 20 | E107: =+'SERVICIO FAENA'!H106 -> 500 | F107: =+'SERVICIO FAENA'!F106 -> 4976.6 | G107: =+'SERVICIO FAENA'!J106 -> 2488300 | H107: =+'SERVICIO DESPOSTE'!W106 -> 0 | I107: =+(G107-J107)+K107+M107+N107+O107+P107+Q107+L107+H107 -> 2488300 | J107: =+MENUDENCIAS!I106 -> 0 | K107: =+MENUDENCIAS!O106 -> 0 | L107: =+MENUDENCIAS!P106 -> 0 | M107: =+RENDERING!H105 -> 0 | N107: =+RENDERING!F105 -> 0 | O107: =+RENDERING!J105 -> 0 | P107: =+CUEROS!N108 -> 0 | Q107: =+'GRASA DREASING'!G105 -> 0
B108: =+'SERVICIO FAENA'!A107 -> 0 | C108: =+'SERVICIO FAENA'!B107 -> 0 | D108: =+'SERVICIO FAENA'!C107 -> 0 | E108: =+'SERVICIO FAENA'!H107 -> 0 | F108: =+'SERVICIO FAENA'!F107 -> 0 | G108: =+'SERVICIO FAENA'!J107 -> 0 | H108: =+'SERVICIO DESPOSTE'!W107 -> 0 | I108: =+(G108-J108)+K108+M108+N108+O108+P108+Q108+L108+H108 -> 0 | J108: =+MENUDENCIAS!I107 -> 0 | K108: =+MENUDENCIAS!O107 -> 0 | L108: =+MENUDENCIAS!P107 -> 0 | M108: =+RENDERING!H106 -> 0 | N108: =+RENDERING!F106 -> 0 | O108: =+RENDERING!J106 -> 0 | P108: =+CUEROS!N109 -> 0 | Q108: =+'GRASA DREASING'!G106 -> 0
...

Sheet SERVICIO FAENA
A1: Nº TROPA | B1: USUARIO | C1: CANTIDAD DE ANIMALES | D1: KG PIE | E1: FECHA FAENA | F1: KG GANCHO | G1: RINDE % | H1: $/kg SERVICIO S/RECUPERO | I1: $/KG SERV. C/RECUPERO | J1: TOTAL $ X SERV. + 21% IVA | K1: TASA INSP. VET. (X CAB.) | L1: ARANCEL IPCVA (X CAB.) | M1: TOTAL $ FACTURA C/IMP. | N1: Nº FACTURA | O1: FECHA FACTURA | P1: FECHA PAGO | R1: MONTO DEPOSITADO | S1: ESTADO PAG. | T1: OBSERVACIONES
K2: 392.78 | L2: 535
A3: 1 | B3: MORAGA | C3: 15 | D3: 5052 | E3: 46024 | F3: 2940.3 | G3: =+F3/D3 -> 0.58200713 | H3: 335 | J3: =+H3*F3 -> 985000.5 | K3: =$K$2*C3 -> 5891.7 | L3: 5625 | M3: =+(J3*1.21)+K3+L3 -> 1203367.3 | N3: 00004-00000388 | O3: 46027 | P3: 46029 | Q3: =+P3-O3 -> 2 | R3: 1203367.3 | S3: =+R3-M3 -> 0.0049999999
A4: 2 | B4: GANADERA NORTE NEUQUINO | C4: 43 | D4: 16831 | E4: 46024 | F4: 9891.8 | G4: =+F4/D4 -> 0.58771315 | H4: 335 | J4: =+H4*F4 -> 3313753 | K4: =$K$2*C4 -> 16889.54 | L4: 16125 | M4: =+(J4*1.21)+K4+L4 -> 4042655.7 | N4: 00004-00000387 | O4: 46027 | P4: 46029 | Q4: =+P4-O4 -> 2 | R4: 4042655.7 | S4: =+R4-M4 -> 0
A5: 3 | B5: GANADERA NORTE NEUQUINO | C5: 40 | D5: 14972 | E5: 46027 | F5: 8567.8 | G5: =+F5/D5 -> 0.57225488 | H5: 335 | J5: =+H5*F5 -> 2870213 | K5: =$K$2*C5 -> 15711.2 | L5: 15000 | M5: =+(J5*1.21)+K5+L5 -> 3503668.9 | N5: 00004-00000393 | O5: 46029 | P5: 46034 | Q5: =+P5-O5 -> 5 | R5: 3503668.9 | S5: =+R5-M5 -> 0
A6: 4 | B6: DOS DE FIERRO SA | C6: 25 | D6: 8989 | E6: 46027 | F6: 5030.4 | G6: =+F6/D6 -> 0.55961731 | H6: 335 | J6: =+H6*F6 -> 1685184 | K6: =$K$2*C6 -> 9819.5 | L6: 9375 | M6: =+(J6*1.21)+K6+L6 -> 2058267.1 | N6: 00004-00000390 | O6: 46028 | P6: 46038 | Q6: =+P6-O6 -> 10 | R6: 2058267.1 | S6: =+R6-M6 -> 0 | T6: E-CHEQ
A7: 5 | B7: DISTRIBUIDORA DE LA PATAGONIA | C7: 30 | D7: 11530 | E7: 46027 | F7: 6743.3 | G7: =+F7/D7 -> 0.58484822 | H7: 335 | J7: =+H7*F7 -> 2259005.5 | K7: =$K$2*C7 -> 11783.4 | L7: 11250 | M7: =+(J7*1.21)+K7+L7 -> 2756430.1 | N7: 00004-00000389 | O7: 46028 | P7: 46028 | Q7: =+P7-O7 -> 0 | R7: 2756430.1 | S7: =+R7-M7 -> 0.0050000004
A8: 6 | B8: DISTRIBUIDORA DE LA PATAGONIA | C8: 15 | D8: 5216 | E8: 46028 | F8: 3075.2 | G8: =+F8/D8 -> 0.58957055 | H8: 335 | J8: =+H8*F8 -> 1030192 | K8: =$K$2*C8 -> 5891.7 | L8: 5625 | M8: =+(J8*1.21)+K8+L8 -> 1258049 | N8: 00004-00000391 | O8: 46028 | P8: 46028 | Q8: =+P8-O8 -> 0 | R8: 1258049 | S8: =+R8-M8 -> 0
A9: 7 | B9: MUCA SAS | C9: 35 | D9: 17870 | E9: 46028 | F9: 10641.5 | G9: =+F9/D9 -> 0.59549524 | H9: 335 | J9: =+H9*F9 -> 3564902.5 | K9: =$K$2*C9 -> 13747.3 | L9: =$L$2*C9 -> 18725 | M9: =+(J9*1.21)+K9+L9 -> 4346004.3 | N9: 00004-00000395 | O9: 46030 | P9: 46045 | Q9: =+P9-O9 -> 15 | R9: 4346004.3 | S9: =+R9-M9 -> 0.0050000008 | T9: E-CHEQ SALDO
A10: 8 | B10: MUCA SAS | C10: 5 | D10: 2714 | E10: 46028 | F10: 1585.2 | G10: =+F10/D10 -> 0.58408254 | H10: 335 | J10: =+H10*F10 -> 531042 | K10: =$K$2*C10 -> 1963.9 | L10: =$L$2*C10 -> 2675 | M10: =+(J10*1.21)+K10+L10 -> 647199.72 | N10: 00004-00000395 | O10: 46030 | P10: 46045 | Q10: =+P10-O10 -> 15 | R10: 647199.72 | S10: =+R10-M10 -> 0 | T10: E-CHEQ
A11: 9 | B11: MUCA SAS | C11: 10 | D11: 4777 | E11: 46028 | F11: 2712.6 | G11: =+F11/D11 -> 0.56784593 | H11: 335 | J11: =+H11*F11 -> 908721 | K11: =$K$2*C11 -> 3927.8 | L11: =$L$2*C11 -> 5350 | M11: =+(J11*1.21)+K11+L11 -> 1108830.2 | N11: 00004-00000395 | O11: 46030 | P11: 46045 | Q11: =+P11-O11 -> 15 | R11: 1108830.2 | S11: =+R11-M11 -> 0 | T11: E-CHEQ
A12: 10 | B12: MORAGA | C12: 15 | D12: 6180 | E12: 46028 | F12: 3623.5 | G12: =+F12/D12 -> 0.58632686 | H12: 335 | J12: =+H12*F12 -> 1213872.5 | K12: =$K$2*C12 -> 5891.7 | L12: 5625 | M12: =+(J12*1.21)+K12+L12 -> 1480302.4 | N12: 00004-00000394 | O12: 46029 | P12: 46029 | Q12: =+P12-O12 -> 0 | R12: 1480302.7 | S12: =+R12-M12 -> 0.265
A13: 11 | B13: FERREYRA MARTIN | C13: 20 | D13: 6150 | E13: 46029 | F13: 3381.6 | G13: =+F13/D13 -> 0.54985366 | H13: 335 | J13: =+H13*F13 -> 1132836 | K13: =$K$2*C13 -> 7855.6 | L13: =$L$2*C13 -> 10700 | M13: =+(J13*1.21)+K13+L13 -> 1389287.2 | N13: 00004-00000396 | O13: 46031 | P13: 46036 | Q13: =+P13-O13 -> 5 | R13: 1389287.2 | S13: =+R13-M13 -> 0
A14: 12 | B14: FERREYRA MARTIN | C14: 3 | D14: 825 | E14: 46029 | F14: 467.9 | G14: =+F14/D14 -> 0.56715152 | H14: 335 | J14: =+H14*F14 -> 156746.5 | K14: =$K$2*C14 -> 1178.34 | L14: =$L$2*C14 -> 1605 | M14: =+(J14*1.21)+K14+L14 -> 192446.6 | N14: =+N13 -> 00004-00000396 | O14: 46031 | P14: 46036 | Q14: =+P14-O14 -> 5 | R14: 192446.59 | S14: =+R14-M14 -> -0.015
A15: 13 | B15: GANADERA NORTE NEUQUINO | C15: 40 | D15: 16040 | E15: 46029 | F15: 8946.1 | G15: =+F15/D15 -> 0.55773691 | H15: 335 | J15: =+H15*F15 -> 2996943.5 | K15: =$K$2*C15 -> 15711.2 | L15: =$L$2*C15 -> 21400 | M15: =+(J15*1.21)+K15+L15 -> 3663412.8 | N15: 00004-00000397 | O15: 46031 | P15: 46034 | Q15: =+P15-O15 -> 3 | R15: 3663412.8 | S15: =+R15-M15 -> 0.0049999999
A16: 14 | B16: FRIGORIFICO DE LA PATAGONIA SRL | C16: 35 | D16: 10198 | E16: 46030 | F16: 5797.4 | G16: =+F16/D16 -> 0.56848402 | H16: 335 | J16: =+H16*F16 -> 1942129 | K16: =$K$2*C16 -> 13747.3 | L16: =$L$2*C16 -> 18725 | M16: =+(J16*1.21)+K16+L16 -> 2382448.4 | N16: 00004-00000398 | O16: 46031 | P16: 46041 | Q16: =+P16-O16 -> 10 | R16: 2382448.4 | S16: =+R16-M16 -> 0
A17: 15 | B17: GANADERA NORTE NEUQUINO | C17: 46 | D17: 16054 | E17: 46031 | F17: 9276.2 | G17: =+F17/D17 -> 0.57781238 | H17: 335 | J17: =+H17*F17 -> 3107527 | K17: =$K$2*C17 -> 18067.88 | L17: =$L$2*C17 -> 24610 | M17: =+(J17*1.21)+K17+L17 -> 3802785.6 | N17: 00004-00000400 | O17: 46035 | P17: 46038 | Q17: =+P17-O17 -> 3 | R17: 3802785.5 | S17: =+R17-M17 -> 0
A18: 16 | B18: MORAGA | C18: 15 | D18: 6402 | E18: 46031 | F18: 3771.7 | G18: =+F18/D18 -> 0.58914402 | H18: 335 | J18: =+H18*F18 -> 1263519.5 | K18: =$K$2*C18 -> 5891.7 | L18: =$L$2*C18 -> 8025 | M18: =+(J18*1.21)+K18+L18 -> 1542775.3 | N18: 00004-00000401 | O18: 46035 | P18: 46035 | Q18: =+P18-O18 -> 0 | R18: 1542775.3 | S18: =+R18-M18 -> 0.0050000001
A19: 17 | B19: LASAGNO JORGE ALBERTO | C19: 17 | D19: 6546 | E19: 46031 | F19: 3815 | G19: =+F19/D19 -> 0.58279866 | H19: 335 | J19: =+H19*F19 -> 1278025 | K19: =$K$2*C19 -> 6677.26 | L19: =$L$2*C19 -> 9095 | M19: =+(J19*1.21)+K19+L19 -> 1562182.5 | N19: 00004-00000399 | O19: 46032 | P19: 46032 | Q19: =+P19-O19 -> 0 | R19: 1562182.5 | S19: =+R19-M19 -> 0
A20: 18 | B20: GANADERA NORTE NEUQUINO | C20: 43 | D20: 15144 | E20: 46034 | F20: 8837.3 | G20: =+F20/D20 -> 0.58355124 | H20: 335 | J20: =+H20*F20 -> 2960495.5 | K20: =$K$2*C20 -> 16889.54 | L20: =$L$2*C20 -> 23005 | M20: =+(J20*1.21)+K20+L20 -> 3622094.1 | N20: 00004-00000402 | O20: 46034 | P20: 46041 | Q20: =+P20-O20 -> 7 | R20: 3622094.1 | S20: =+R20-M20 -> 0.0050000008
A21: 19 | B21: DOS DE FIERRO SA | C21: 25 | D21: 9054 | E21: 46034 | F21: 5048.5 | G21: =+F21/D21 -> 0.55759885 | H21: 335 | J21: =+H21*F21 -> 1691247.5 | K21: =$K$2*C21 -> 9819.5 | L21: =$L$2*C21 -> 13375 | M21: =+(J21*1.21)+K21+L21 -> 2069604 | N21: 00004-00000403 | O21: 46034 | P21: 46041 | Q21: =+P21-O21 -> 7 | R21: 2069603 | S21: =+R21-M21 -> -0.975
A22: 20 | B22: FERREYRA MARTIN | C22: 15 | D22: 4722 | E22: 46034 | F22: 2689.9 | G22: =+F22/D22 -> 0.56965269 | H22: 335 | J22: =+H22*F22 -> 901116.5 | K22: =$K$2*C22 -> 5891.7 | L22: =$L$2*C22 -> 8025 | M22: =+(J22*1.21)+K22+L22 -> 1104267.7 | N22: 00004-00000404 | O22: 46034 | P22: 46041 | Q22: =+P22-O22 -> 7 | R22: 1104267.7 | S22: =+R22-M22 -> -0.0050000001
A23: 21 | B23: MUCA SAS | C23: 8 | D23: 3551 | E23: 46035 | F23: 2076.3 | G23: =+F23/D23 -> 0.58470853 | H23: 335 | J23: =+H23*F23 -> 695560.5 | K23: =$K$2*C23 -> 3142.24 | L23: =$L$2*C23 -> 4280 | M23: =+(J23*1.21)+K23+L23 -> 849050.45 | N23: 00004-00000405 | O23: 46036 | P23: 46045 | Q23: =+P23-O23 -> 9 | R23: 849050.45 | S23: =+R23-M23 -> 0.0049999999 | T23: E-CHEQ
A24: 22 | B24: MUCA SAS | C24: 7 | D24: 3139 | E24: 46035 | F24: 1852.3 | G24: =+F24/D24 -> 0.59009239 | H24: 335 | J24: =+H24*F24 -> 620520.5 | K24: =$K$2*C24 -> 2749.46 | L24: =$L$2*C24 -> 3745 | M24: =+(J24*1.21)+K24+L24 -> 757324.26 | N24: =+N23 -> 00004-00000405 | O24: 46036 | P24: 46045 | Q24: =+P24-O24 -> 9 | R24: 757324.27 | S24: =+R24-M24 -> 0.0050000001 | T24: E-CHEQ
A25: 23 | B25: MUCA SAS | C25: 5 | D25: 3736 | E25: 46035 | F25: 2266.5 | G25: =+F25/D25 -> 0.60666488 | H25: 335 | J25: =+H25*F25 -> 759277.5 | K25: =$K$2*C25 -> 1963.9 | L25: =$L$2*C25 -> 2675 | M25: =+(J25*1.21)+K25+L25 -> 923364.68 | N25: =+N24 -> 00004-00000405 | O25: 46036 | P25: 46045 | Q25: =+P25-O25 -> 9 | R25: 923364.68 | S25: =+R25-M25 -> 0.005 | T25: E-CHEQ
A26: 24 | B26: FERREYRA MARTIN | C26: 30 | D26: 10277 | E26: 46036 | F26: 5913.5 | G26: =+F26/D26 -> 0.57541111 | H26: 335 | J26: =+H26*F26 -> 1981022.5 | K26: =$K$2*C26 -> 11783.4 | L26: =$L$2*C26 -> 16050 | M26: =+(J26*1.21)+K26+L26 -> 2424870.6 | N26: 00004-00000406 | O26: 46037 | P26: 46045 | Q26: =+P26-O26 -> 8 | R26: 2424870.6 | S26: =+R26-M26 -> 0.0049999999
A27: 25 | B27: FERREYRA ALBERTO | C27: 6 | D27: 1839 | E27: 46036 | F27: 1026 | G27: =+F27/D27 -> 0.55791191 | H27: 335 | J27: =+H27*F27 -> 343710 | K27: =$K$2*C27 -> 2356.68 | L27: =$L$2*C27 -> 3210 | M27: =+(J27*1.21)+K27+L27 -> 421455.78 | N27: 00004-00000407 | O27: 46037 | P27: 46038 | Q27: =+P27-O27 -> 1 | R27: 421455.78 | S27: =+R27-M27 -> 0
A28: 26 | B28: FRIGORIFICO DE LA PATAGONIA SRL | C28: 50 | D28: 20868 | E28: 46038 | F28: 11388.5 | G28: =+F28/D28 -> 0.54573989 | H28: 335 | J28: =+H28*F28 -> 3815147.5 | K28: =$K$2*C28 -> 19639 | L28: =$L$2*C28 -> 26750 | M28: =+(J28*1.21)+K28+L28 -> 4662717.5 | N28: 00004-00000408 | O28: 46041 | P28: 46041 | Q28: =+P28-O28 -> 0 | R28: 4662717.5 | S28: =+R28-M28 -> 0.0050000008
A29: 27 | B29: GANADERA NORTE NEUQUINO | C29: 40 | D29: 16159 | E29: 46041 | F29: 9184 | G29: =+F29/D29 -> 0.568352 | H29: 420 | J29: =+H29*F29 -> 3857280 | K29: =$K$2*C29 -> 15711.2 | L29: =$L$2*C29 -> 21400 | M29: =+(J29*1.21)+K29+L29 -> 4704420 | N29: 00004-00000409 | O29: 46043 | P29: 46050 | Q29: =+P29-O29 -> 7 | R29: 4704420 | S29: =+R29-M29 -> 0
A30: 28 | B30: DOS DE FIERRO SA | C30: 26 | D30: 9452 | E30: 46041 | F30: 5329.9 | G30: =+F30/D30 -> 0.56389124 | H30: 420 | J30: =+H30*F30 -> 2238558 | K30: =$K$2*C30 -> 10212.28 | L30: =$L$2*C30 -> 13910 | M30: =+(J30*1.21)+K30+L30 -> 2732777.5 | N30: 00004-00000410 | O30: 46043 | P30: 46057 | Q30: =+P30-O30 -> 14 | R30: 2732777.5 | S30: =+R30-M30 -> 0
A31: 29 | B31: FERREYRA MARTIN | C31: 15 | D31: 5044 | E31: 46041 | F31: 2923.1 | G31: =+F31/D31 -> 0.57952022 | H31: 420 | J31: =+H31*F31 -> 1227702 | K31: =$K$2*C31 -> 5891.7 | L31: =$L$2*C31 -> 8025 | M31: =+(J31*1.21)+K31+L31 -> 1499436.1 | N31: 00004-00000411 | O31: 46043 | P31: 46048 | Q31: =+P31-O31 -> 5 | R31: 1499436.1 | S31: =+R31-M31 -> 0
A32: 30 | B32: BOSQUES AMADOS SRL | C32: 18 | D32: =356+6343 -> 6699 | E32: 20-21/01/2026 | F32: =194.6+3633.1 -> 3827.7 | G32: =+F32/D32 -> 0.57138379 | H32: 420 | J32: =+H32*F32 -> 1607634 | K32: =$K$2*C32 -> 7070.04 | L32: =$L$2*C32 -> 9630 | M32: =+(J32*1.21)+K32+L32 -> 1961937.2 | N32: 00004-00000412 | O32: 46045 | P32: 46055 | Q32: =+P32-O32 -> 10 | R32: 1961937.2 | S32: =+R32-M32 -> 0
A33: 31 | B33: MUCA SAS | C33: 50 | D33: 24991 | E33: 46042 | F33: 14763.6 | G33: =+F33/D33 -> 0.59075667 | H33: 420 | J33: =+H33*F33 -> 6200712 | K33: =$K$2*C33 -> 19639 | L33: =$L$2*C33 -> 26750 | M33: =+(J33*1.21)+K33+L33 -> 7549250.5 | N33: 00004-00000413 | O33: 46045 | P33: 46059 | Q33: =+P33-O33 -> 14 | R33: 7549250.5 | S33: =+R33-M33 -> 0
A34: 32 | B34: FERREYRA ALBERTO | C34: 8 | D34: 2803 | E34: 46044 | F34: 1669.6 | G34: =+F34/D34 -> 0.59564752 | H34: 420 | J34: =+H34*F34 -> 701232 | K34: =$K$2*C34 -> 3142.24 | L34: =$L$2*C34 -> 4280 | M34: =+(J34*1.21)+K34+L34 -> 855912.96 | N34: 00004-00000414 | O34: 46045 | P34: 46050 | Q34: =+P34-O34 -> 5 | R34: 855912.96 | S34: =+R34-M34 -> 0
A35: 33 | B35: FERREYRA MARTIN | C35: 20 | D35: 7197 | E35: 46044 | F35: 4225.7 | G35: =+F35/D35 -> 0.58714742 | H35: 420 | J35: =+H35*F35 -> 1774794 | K35: =$K$2*C35 -> 7855.6 | L35: =$L$2*C35 -> 10700 | M35: =+(J35*1.21)+K35+L35 -> 2166056.3 | N35: 00004-00000415 | O35: 46045 | P35: 46055 | Q35: =+P35-O35 -> 10 | R35: 2166156.3 | S35: =+R35-M35 -> 100
A36: 34 | B36: FRIGORIFICO DE LA PATAGONIA SRL | C36: 15 | D36: 5823 | E36: 46045 | F36: 3412.6 | G36: =+F36/D36 -> 0.5860553 | H36: 420 | J36: =+H36*F36 -> 1433292 | K36: =$K$2*C36 -> 5891.7 | L36: =$L$2*C36 -> 8025 | M36: =+(J36*1.21)+K36+L36 -> 1748200 | N36: 00004-00000416 | O36: 46045 | P36: 46057 | Q36: =+P36-O36 -> 12 | R36: 1748200 | S36: =+R36-M36 -> 0
A37: 35 | B37: MUCA SAS | C37: 13 | D37: 5332 | E37: 46045 | F37: 2920.2 | G37: =+F37/D37 -> 0.54767442 | H37: 420 | J37: =+H37*F37 -> 1226484 | K37: =$K$2*C37 -> 5106.14 | L37: =$L$2*C37 -> 6955 | M37: =+(J37*1.21)+K37+L37 -> 1496106.8 | N37: 00004-00000417 | O37: 46045 | P37: 46059 | Q37: =+P37-O37 -> 14 | R37: 1496106.8 | S37: =+R37-M37 -> 0
A38: 36 | B38: MUCA SAS | C38: 15 | D38: 7438 | E38: 46045 | F38: 4307.2 | G38: =+F38/D38 -> 0.5790804 | H38: 420 | J38: =+H38*F38 -> 1809024 | K38: =$K$2*C38 -> 5891.7 | L38: =$L$2*C38 -> 8025 | M38: =+(J38*1.21)+K38+L38 -> 2202835.7 | N38: 00004-00000417 | O38: 46045 | P38: 46059 | Q38: =+P38-O38 -> 14 | R38: 2202835.7 | S38: =+R38-M38 -> 0
A39: 37 | B39: FERREYRA MARTIN | C39: 15 | D39: 4501 | E39: 46048 | F39: 2620.9 | G39: =+F39/D39 -> 0.58229282 | H39: 420 | J39: =+H39*F39 -> 1100778 | K39: =$K$2*C39 -> 5891.7 | L39: =$L$2*C39 -> 8025 | M39: =+(J39*1.21)+K39+L39 -> 1345858.1 | N39: 00004-00000419 | O39: 46049 | P39: 46057 | Q39: =+P39-O39 -> 8 | R39: 1345858.1 | S39: =+R39-M39 -> 0
A40: 38 | B40: FRIGORIFICO DE LA PATAGONIA SRL | C40: 26 | D40: 9703 | E40: 46048 | F40: 5472.9 | G40: =+F40/D40 -> 0.56404205 | H40: 420 | J40: =+H40*F40 -> 2298618 | K40: =$K$2*C40 -> 10212.28 | L40: =$L$2*C40 -> 13910 | M40: =+(J40*1.21)+K40+L40 -> 2805450.1 | N40: 00004-00000418 | O40: 46049 | P40: 46057 | Q40: =+P40-O40 -> 8 | R40: 2805450.1 | S40: =+R40-M40 -> 0 | T40: Faena Dos de Fierro
...

Sheet SERVICIO DESPOSTE
A1: Nº TROPA | B1: USUARIO | C1: FAENA | H1: SERVIO DESPOSTE
C2: Nº ANIMAL | D2: KG PIE | E2: FECHA FAENA | F2: KG GANCHO | G2: RINDE % | H2: 1/2 RES DER. | I2: 1/2 RES IZQ | J2: MERMA % | K2: KG ASADO | L2: KG DELANTERO | M2: KG TRASERO | N2: TOTAL KG ING. | O2: KG CARNE | P2: $/KG CARNE | Q2: KG CARNE C/H | R2: $/KG CARNE C/H | S2: HUESO | T2: GRASA | U2: RINDE | V2: DIF. +/- | W2: TOTAL FAC. | X2: TOTAL FAC. CON IMP. | Y2: Nº FAC. | Z2: FECHA FAC. | AA2: FECHA PAGO | AB2: Monto depositado | AC2: ESTADO
A3: =+'SERVICIO FAENA'!A3 -> 1 | B3: =+'SERVICIO FAENA'!B3 -> MORAGA | E3: =+'SERVICIO FAENA'!E3 -> 46024 | G3: =+F3/D3 -> #DIV/0! | J3: =+((F3-(H3+I3))/F3) -> #DIV/0! | N3: =SUM(K3:M3) -> 0 | P3: 880 | R3: 260 | W3: =+(P3*O3)+(R3*Q3) -> 0 | X3: =+((O3*P3)+(Q3*R3))*1.21 -> 0
A4: =+'SERVICIO FAENA'!A4 -> 2 | B4: =+'SERVICIO FAENA'!B4 -> GANADERA NORTE NEUQUINO | E4: =+'SERVICIO FAENA'!E4 -> 46024 | G4: =+F4/D4 -> #DIV/0! | J4: =+((F4-(H4+I4))/F4) -> #DIV/0! | N4: =SUM(K4:M4) -> 0 | P4: 880 | R4: 260 | W4: =+(P4*O4)+(R4*Q4) -> 0 | X4: =+((O4*P4)+(Q4*R4))*1.21 -> 0
A5: =+'SERVICIO FAENA'!A5 -> 3 | B5: =+'SERVICIO FAENA'!B5 -> GANADERA NORTE NEUQUINO | E5: =+'SERVICIO FAENA'!E5 -> 46027 | G5: =+F5/D5 -> #DIV/0! | J5: =+((F5-(H5+I5))/F5) -> #DIV/0! | N5: =SUM(K5:M5) -> 0 | P5: 880 | R5: 260 | W5: =+(P5*O5)+(R5*Q5) -> 0 | X5: =+((O5*P5)+(Q5*R5))*1.21 -> 0
A6: =+'SERVICIO FAENA'!A6 -> 4 | B6: =+'SERVICIO FAENA'!B6 -> DOS DE FIERRO SA | E6: =+'SERVICIO FAENA'!E6 -> 46027 | G6: =+F6/D6 -> #DIV/0! | J6: =+((F6-(H6+I6))/F6) -> #DIV/0! | N6: =SUM(K6:M6) -> 0 | P6: 880 | R6: 260 | W6: =+(P6*O6)+(R6*Q6) -> 0 | X6: =+((O6*P6)+(Q6*R6))*1.21 -> 0
A7: =+'SERVICIO FAENA'!A7 -> 5 | B7: =+'SERVICIO FAENA'!B7 -> DISTRIBUIDORA DE LA PATAGONIA | E7: =+'SERVICIO FAENA'!E7 -> 46027 | G7: =+F7/D7 -> #DIV/0! | J7: =+((F7-(H7+I7))/F7) -> #DIV/0! | N7: =SUM(K7:M7) -> 0 | P7: 880 | R7: 260 | W7: =+(P7*O7)+(R7*Q7) -> 0 | X7: =+((O7*P7)+(Q7*R7))*1.21 -> 0
A8: =+'SERVICIO FAENA'!A8 -> 6 | B8: =+'SERVICIO FAENA'!B8 -> DISTRIBUIDORA DE LA PATAGONIA | E8: =+'SERVICIO FAENA'!E8 -> 46028 | G8: =+F8/D8 -> #DIV/0! | J8: =+((F8-(H8+I8))/F8) -> #DIV/0! | N8: =SUM(K8:M8) -> 0 | P8: 880 | R8: 260 | W8: =+(P8*O8)+(R8*Q8) -> 0 | X8: =+((O8*P8)+(Q8*R8))*1.21 -> 0
A9: =+'SERVICIO FAENA'!A9 -> 7 | B9: =+'SERVICIO FAENA'!B9 -> MUCA SAS | E9: =+'SERVICIO FAENA'!E9 -> 46028 | G9: =+F9/D9 -> #DIV/0! | J9: =+((F9-(H9+I9))/F9) -> #DIV/0! | N9: =SUM(K9:M9) -> 0 | P9: 880 | R9: 260 | W9: =+(P9*O9)+(R9*Q9) -> 0 | X9: =+((O9*P9)+(Q9*R9))*1.21 -> 0
A10: =+'SERVICIO FAENA'!A10 -> 8 | B10: =+'SERVICIO FAENA'!B10 -> MUCA SAS | E10: =+'SERVICIO FAENA'!E10 -> 46028 | G10: =+F10/D10 -> #DIV/0! | J10: =+((F10-(H10+I10))/F10) -> #DIV/0! | N10: =SUM(K10:M10) -> 0 | P10: 880 | R10: 260 | W10: =+(P10*O10)+(R10*Q10) -> 0 | X10: =+((O10*P10)+(Q10*R10))*1.21 -> 0
A11: =+'SERVICIO FAENA'!A11 -> 9 | B11: =+'SERVICIO FAENA'!B11 -> MUCA SAS | E11: =+'SERVICIO FAENA'!E11 -> 46028 | G11: =+F11/D11 -> #DIV/0! | J11: =+((F11-(H11+I11))/F11) -> #DIV/0! | N11: =SUM(K11:M11) -> 0 | P11: 880 | R11: 260 | W11: =+(P11*O11)+(R11*Q11) -> 0 | X11: =+((O11*P11)+(Q11*R11))*1.21 -> 0
A12: =+'SERVICIO FAENA'!A12 -> 10 | B12: =+'SERVICIO FAENA'!B12 -> MORAGA | E12: =+'SERVICIO FAENA'!E12 -> 46028 | G12: =+F12/D12 -> #DIV/0! | J12: =+((F12-(H12+I12))/F12) -> #DIV/0! | N12: =SUM(K12:M12) -> 0 | P12: 880 | R12: 260 | W12: =+(P12*O12)+(R12*Q12) -> 0 | X12: =+((O12*P12)+(Q12*R12))*1.21 -> 0
A13: =+'SERVICIO FAENA'!A13 -> 11 | B13: =+'SERVICIO FAENA'!B13 -> FERREYRA MARTIN | E13: =+'SERVICIO FAENA'!E13 -> 46029 | G13: =+F13/D13 -> #DIV/0! | J13: =+((F13-(H13+I13))/F13) -> #DIV/0! | N13: =SUM(K13:M13) -> 0 | P13: 880 | R13: 260 | W13: =+(P13*O13)+(R13*Q13) -> 0 | X13: =+((O13*P13)+(Q13*R13))*1.21 -> 0
A14: =+'SERVICIO FAENA'!A14 -> 12 | B14: =+'SERVICIO FAENA'!B14 -> FERREYRA MARTIN | E14: =+'SERVICIO FAENA'!E14 -> 46029 | G14: =+F14/D14 -> #DIV/0! | J14: =+((F14-(H14+I14))/F14) -> #DIV/0! | N14: =SUM(K14:M14) -> 0 | P14: 880 | R14: 260 | W14: =+(P14*O14)+(R14*Q14) -> 0 | X14: =+((O14*P14)+(Q14*R14))*1.21 -> 0
... A40: =+'SERVICIO FAENA'!A40 -> 38 | B40: =+'SERVICIO FAENA'!B40 -> FRIGORIFICO DE LA PATAGONIA SRL | E40: =+'SERVICIO FAENA'!E40 -> 46048 | G40: =+F40/D40 -> #DIV/0! | J40: =+((F40-(H40+I40))/F40) -> #DIV/0! | N40: =SUM(K40:M40) -> 0 | P40: 880 | R40: 260 | W40: =+(P40*O40)+(R40*Q40) -> 0 | X40: =+((O40*P40)+(Q40*R40))*1.21 -> 0
A41: =+'SERVICIO FAENA'!A41 -> 39 | B41: =+'SERVICIO FAENA'!B41 -> BOSQUES AMADOS SRL | C41: 5 | D41: 2142 | E41: =+'SERVICIO FAENA'!E41 -> 46049 | F41: 1207.4 | G41: =+F41/D41 -> 0.5636788 | H41: 589.6 | I41: 594.9 | J41: =+((F41-(H41+I41))/F41) -> 0.018966374 | K41: 279.34 | L41: 351.02 | M41: 554.8 | N41: =SUM(K41:M41) -> 1185.16 | O41: 704.59 | P41: 880 | Q41: 279.34 | R41: 260 | S41: 192.7 | T41: 8 | U41: =+(Q41+O41)/N41 -> 0.83020858 | V41: =+(T41+S41+Q41+O41)-N41 -> -0.53 | W41: =+(P41*O41)+(R41*Q41) -> 692667.6 | X41: =+((O41*P41)+(Q41*R41))*1.21 -> 838127.8 | AC41: =+AB41-X41 -> -838127.8
A42: =+'SERVICIO FAENA'!A42 -> 40 | B42: =+'SERVICIO FAENA'!B42 -> MUCA SAS | E42: =+'SERVICIO FAENA'!E42 -> 46049 | G42: =+F42/D42 -> #DIV/0! | J42: =+((F42-(H42+I42))/F42) -> #DIV/0! | N42: =SUM(K42:M42) -> 0 | P42: 880 | R42: 260 | W42: =+(P42*O42)+(R42*Q42) -> 0 | X42: =+((O42*P42)+(Q42*R42))*1.21 -> 0
A43: =+'SERVICIO FAENA'!A43 -> 41 | B43: =+'SERVICIO FAENA'!B43 -> MUCA SAS | E43: =+'SERVICIO FAENA'!E43 -> 46049 | G43: =+F43/D43 -> #DIV/0! | J43: =+((F43-(H43+I43))/F43) -> #DIV/0! | N43: =SUM(K43:M43) -> 0 | P43: 880 | R43: 260 | W43: =+(P43*O43)+(R43*Q43) -> 0 | X43: =+((O43*P43)+(Q43*R43))*1.21 -> 0
A44: =+'SERVICIO FAENA'!A44 -> 42 | B44: =+'SERVICIO FAENA'!B44 -> FERREYRA MARTIN | E44: =+'SERVICIO FAENA'!E44 -> 46050 | G44: =+F44/D44 -> #DIV/0! | J44: =+((F44-(H44+I44))/F44) -> #DIV/0! | N44: =SUM(K44:M44) -> 0 | P44: 880 | R44: 260 | W44: =+(P44*O44)+(R44*Q44) -> 0 | X44: =+((O44*P44)+(Q44*R44))*1.21 -> 0
A45: =+'SERVICIO FAENA'!A45 -> 43 | B45: =+'SERVICIO FAENA'!B45 -> FERREYRA MARTIN | E45: =+'SERVICIO FAENA'!E45 -> 46050 | G45: =+F45/D45 -> #DIV/0! | J45: =+((F45-(H45+I45))/F45) -> #DIV/0! | N45: =SUM(K45:M45) -> 0 | P45: 880 | R45: 260 | W45: =+(P45*O45)+(R45*Q45) -> 0 | X45: =+((O45*P45)+(Q45*R45))*1.21 -> 0
A46: =+'SERVICIO FAENA'!A46 -> 44 | B46: =+'SERVICIO FAENA'!B46 -> FERREYRA ALBERTO | E46: =+'SERVICIO FAENA'!E46 -> 46050 | G46: =+F46/D46 -> #DIV/0! | J46: =+((F46-(H46+I46))/F46) -> #DIV/0! | N46: =SUM(K46:M46) -> 0 | P46: 880 | R46: 260 | W46: =+(P46*O46)+(R46*Q46) -> 0 | X46: =+((O46*P46)+(Q46*R46))*1.21 -> 0
A47: =+'SERVICIO FAENA'!A47 -> 45 | B47: =+'SERVICIO FAENA'!B47 -> FRIGORIFICO DE LA PATAGONIA SRL | E47: =+'SERVICIO FAENA'!E47 -> 46052 | G47: =+F47/D47 -> #DIV/0! | J47: =+((F47-(H47+I47))/F47) -> #DIV/0! | N47: =SUM(K47:M47) -> 0 | P47: 880 | R47: 260 | W47: =+(P47*O47)+(R47*Q47) -> 0 | X47: =+((O47*P47)+(Q47*R47))*1.21 -> 0
A48: =+'SERVICIO FAENA'!A48 -> 46 | B48: =+'SERVICIO FAENA'!B48 -> FRIGORIFICO DE LA PATAGONIA SRL | E48: =+'SERVICIO FAENA'!E48 -> 46052 | G48: =+F48/D48 -> #DIV/0! | J48: =+((F48-(H48+I48))/F48) -> #DIV/0! | N48: =SUM(K48:M48) -> 0 | P48: 880 | R48: 260 | W48: =+(P48*O48)+(R48*Q48) -> 0 | X48: =+((O48*P48)+(Q48*R48))*1.21 -> 0
A49: =+'SERVICIO FAENA'!A49 -> 47 | B49: =+'SERVICIO FAENA'!B49 -> MUCA SAS | E49: =+'SERVICIO FAENA'!E49 -> 46052 | G49: =+F49/D49 -> #DIV/0! | J49: =+((F49-(H49+I49))/F49) -> #DIV/0! | N49: =SUM(K49:M49) -> 0 | P49: 880 | R49: 260 | W49: =+(P49*O49)+(R49*Q49) -> 0 | X49: =+((O49*P49)+(Q49*R49))*1.21 -> 0
A50: =+'SERVICIO FAENA'!A50 -> 48 | B50: =+'SERVICIO FAENA'!B50 -> MUCA SAS | E50: =+'SERVICIO FAENA'!E50 -> 46052 | G50: =+F50/D50 -> #DIV/0! | J50: =+((F50-(H50+I50))/F50) -> #DIV/0! | N50: =SUM(K50:M50) -> 0 | P50: 880 | R50: 260 | W50: =+(P50*O50)+(R50*Q50) -> 0 | X50: =+((O50*P50)+(Q50*R50))*1.21 -> 0
A51: =+'SERVICIO FAENA'!A51 -> 49 | B51: =+'SERVICIO FAENA'!B51 -> MUCA SAS | E51: =+'SERVICIO FAENA'!E51 -> 46052 | G51: =+F51/D51 -> #DIV/0! | J51: =+((F51-(H51+I51))/F51) -> #DIV/0! | N51: =SUM(K51:M51) -> 0 | P51: 880 | R51: 260 | W51: =+(P51*O51)+(R51*Q51) -> 0 | X51: =+((O51*P51)+(Q51*R51))*1.21 -> 0
A52: =+'SERVICIO FAENA'!A52 -> 50 | B52: =+'SERVICIO FAENA'!B52 -> MUCA SAS | E52: =+'SERVICIO FAENA'!E52 -> 46052 | G52: =+F52/D52 -> #DIV/0! | J52: =+((F52-(H52+I52))/F52) -> #DIV/0! | N52: =SUM(K52:M52) -> 0 | P52: 880 | R52: 260 | W52: =+(P52*O52)+(R52*Q52) -> 0 | X52: =+((O52*P52)+(Q52*R52))*1.21 -> 0
A53: =+'SERVICIO FAENA'!A53 -> 51 | B53: =+'SERVICIO FAENA'!B53 -> GANADERA NORTE NEUQUINO | E53: =+'SERVICIO FAENA'!E53 -> 46055 | G53: =+F53/D53 -> #DIV/0! | J53: =+((F53-(H53+I53))/F53) -> #DIV/0! | N53: =SUM(K53:M53) -> 0 | P53: 880 | R53: 260 | W53: =+(P53*O53)+(R53*Q53) -> 0 | X53: =+((O53*P53)+(Q53*R53))*1.21 -> 0
... A86: =+'SERVICIO FAENA'!A86 -> 84 | B86: =+'SERVICIO FAENA'!B86 -> DOS DE FIERRO SA | E86: =+'SERVICIO FAENA'!E86 -> 46076 | G86: =+F86/D86 -> #DIV/0! | J86: =+((F86-(H86+I86))/F86) -> #DIV/0! | N86: =SUM(K86:M86) -> 0 | P86: 880 | R86: 260 | W86: =+(P86*O86)+(R86*Q86) -> 0 | X86: =+((O86*P86)+(Q86*R86))*1.21 -> 0
A87: =+'SERVICIO FAENA'!A87 -> 85 | B87: =+'SERVICIO FAENA'!B87 -> FERREYRA MARTIN | C87: 7.5 | D87: 3322 | E87: =+'SERVICIO FAENA'!E87 -> 46076 | F87: 1884.7 | G87: =+F87/D87 -> 0.56733895 | H87: 862.4 | I87: 975.4 | J87: =+((F87-(H87+I87))/F87) -> 0.024884597 | K87: 420.56 | L87: 257.3 | M87: 1158.4 | N87: =SUM(K87:M87) -> 1836.26 | O87: 1183.49 | P87: 880 | Q87: 412.4 | R87: 260 | S87: 236.5 | T87: 3 | U87: =+(Q87+O87)/N87 -> 0.86909806 | V87: =+(T87+S87+Q87+O87)-N87 -> -0.87 | W87: =+(P87*O87)+(R87*Q87) -> 1148695.2 | X87: =+((O87*P87)+(Q87*R87))*1.21 -> 1389921.2
A88: =+'SERVICIO FAENA'!A88 -> 86 | B88: =+'SERVICIO FAENA'!B88 -> MUCA SAS | E88: =+'SERVICIO FAENA'!E88 -> 46077 | G88: =+F88/D88 -> #DIV/0! | J88: =+((F88-(H88+I88))/F88) -> #DIV/0! | N88: =SUM(K88:M88) -> 0 | P88: 880 | R88: 260 | W88: =+(P88*O88)+(R88*Q88) -> 0 | X88: =+((O88*P88)+(Q88*R88))*1.21 -> 0
A89: =+'SERVICIO FAENA'!A89 -> 87 | B89: =+'SERVICIO FAENA'!B89 -> BOSQUES AMADOS SRL | E89: =+'SERVICIO FAENA'!E89 -> 46077 | G89: =+F89/D89 -> #DIV/0! | J89: =+((F89-(H89+I89))/F89) -> #DIV/0! | N89: =SUM(K89:M89) -> 0 | P89: 880 | R89: 260 | W89: =+(P89*O89)+(R89*Q89) -> 0 | X89: =+((O89*P89)+(Q89*R89))*1.21 -> 0
A90: =+'SERVICIO FAENA'!A90 -> 88 | B90: =+'SERVICIO FAENA'!B90 -> FERREYRA ALBERTO | E90: =+'SERVICIO FAENA'!E90 -> 46078 | G90: =+F90/D90 -> #DIV/0! | J90: =+((F90-(H90+I90))/F90) -> #DIV/0! | N90: =SUM(K90:M90) -> 0 | P90: 880 | R90: 260 | W90: =+(P90*O90)+(R90*Q90) -> 0 | X90: =+((O90*P90)+(Q90*R90))*1.21 -> 0
A91: =+'SERVICIO FAENA'!A91 -> 89 | B91: =+'SERVICIO FAENA'!B91 -> FERREYRA MARTIN | E91: =+'SERVICIO FAENA'!E91 -> 46078 | G91: =+F91/D91 -> #DIV/0! | J91: =+((F91-(H91+I91))/F91) -> #DIV/0! | N91: =SUM(K91:M91) -> 0 | P91: 880 | R91: 260 | W91: =+(P91*O91)+(R91*Q91) -> 0 | X91: =+((O91*P91)+(Q91*R91))*1.21 -> 0
A92: =+'SERVICIO FAENA'!A92 -> 90 | B92: =+'SERVICIO FAENA'!B92 -> FERREYRA MARTIN | E92: =+'SERVICIO FAENA'!E92 -> 46078 | G92: =+F92/D92 -> #DIV/0! | J92: =+((F92-(H92+I92))/F92) -> #DIV/0! | N92: =SUM(K92:M92) -> 0 | P92: 880 | R92: 260 | W92: =+(P92*O92)+(R92*Q92) -> 0 | X92: =+((O92*P92)+(Q92*R92))*1.21 -> 0
A93: =+'SERVICIO FAENA'!A93 -> 91 | B93: =+'SERVICIO FAENA'!B93 -> FRIGORIFICO DE LA PATAGONIA SRL | E93: =+'SERVICIO FAENA'!E93 -> 46080 | G93: =+F93/D93 -> #DIV/0! | J93: =+((F93-(H93+I93))/F93) -> #DIV/0! | N93: =SUM(K93:M93) -> 0 | P93: 880 | R93: 260 | W93: =+(P93*O93)+(R93*Q93) -> 0 | X93: =+((O93*P93)+(Q93*R93))*1.21 -> 0
A94: =+'SERVICIO FAENA'!A94 -> 92 | B94: =+'SERVICIO FAENA'!B94 -> MAIZALES DE LA PATAGONIA SRL | E94: =+'SERVICIO FAENA'!E94 -> 46080 | G94: =+F94/D94 -> #DIV/0! | J94: =+((F94-(H94+I94))/F94) -> #DIV/0! | N94: =SUM(K94:M94) -> 0 | P94: 880 | R94: 260 | W94: =+(P94*O94)+(R94*Q94) -> 0 | X94: =+((O94*P94)+(Q94*R94))*1.21 -> 0
A95: =+'SERVICIO FAENA'!A95 -> 93 | B95: =+'SERVICIO FAENA'!B95 -> MAIZALES DE LA PATAGONIA SRL | E95: =+'SERVICIO FAENA'!E95 -> 46080 | G95: =+F95/D95 -> #DIV/0! | J95: =+((F95-(H95+I95))/F95) -> #DIV/0! | N95: =SUM(K95:M95) -> 0 | P95: 880 | R95: 260 | W95: =+(P95*O95)+(R95*Q95) -> 0 | X95: =+((O95*P95)+(Q95*R95))*1.21 -> 0
A96: =+'SERVICIO FAENA'!A96 -> 94 | B96: =+'SERVICIO FAENA'!B96 -> FRIGORIFICO DE LA PATAGONIA SRL | E96: =+'SERVICIO FAENA'!E96 -> 46080 | G96: =+F96/D96 -> #DIV/0! | J96: =+((F96-(H96+I96))/F96) -> #DIV/0! | N96: =SUM(K96:M96) -> 0 | P96: 880 | R96: 260 | W96: =+(P96*O96)+(R96*Q96) -> 0 | X96: =+((O96*P96)+(Q96*R96))*1.21 -> 0
A97: =+'SERVICIO FAENA'!A97 -> 95 | B97: =+'SERVICIO FAENA'!B97 -> MUCA SAS | E97: =+'SERVICIO FAENA'!E97 -> 46080 | G97: =+F97/D97 -> #DIV/0! | J97: =+((F97-(H97+I97))/F97) -> #DIV/0! | N97: =SUM(K97:M97) -> 0 | P97: 880 | R97: 260 | W97: =+(P97*O97)+(R97*Q97) -> 0 | X97: =+((O97*P97)+(Q97*R97))*1.21 -> 0
...

Sheet MENUDENCIAS
G1: AREA COMPRAS | K1: AREA VENTA
A2: Nº TROPA | B2: USUARIO | C2: CANTIDAD ANIMALES | D2: KG ACHURAS | E2: KG ACHURAS Decomisadas | F2: KG LAVADITO | G2: VALOR POR KG | H2: VALOR POR UNIDAD | I2: TOTAL FACTURA COMPRA | J2: Nº FACTURA | K2: $/KG + 10.5 IVA | L2: TOTAL | M2: CLIENTE | N2: Nº FACTURA | O2: TOTAL $ FACTURA S/IVA | P2: TOTAL $ FACTURA C/IVA | Q2: FECHA DE PAGO | R2: MONTO DEPOSITADO | S2: ESTADO | T2: OBSERVACIONES
A3: =+'SERVICIO FAENA'!A3 -> 1 | B3: =+'SERVICIO FAENA'!B3 -> MORAGA | C3: =+'SERVICIO FAENA'!C3 -> 15 | D3: 209.1 | E3: 9.96 | L3: =+K3*F3 -> 0 | O3: =+K3*F3 -> 0 | P3: =+(L3*10.5/100)+L3 -> 0 | R3: 0 | S3: =+R3-P3 -> 0
A4: =+'SERVICIO FAENA'!A4 -> 2 | B4: =+'SERVICIO FAENA'!B4 -> GANADERA NORTE NEUQUINO | C4: =+'SERVICIO FAENA'!C4 -> 43 | D4: 677.88 | E4: 1.64 | L4: =+K4*F4 -> 0 | O4: =+K4*F4 -> 0 | P4: =+(L4*10.5/100)+L4 -> 0 | R4: 0 | S4: =+R4-P4 -> 0
A5: =+'SERVICIO FAENA'!A5 -> 3 | B5: =+'SERVICIO FAENA'!B5 -> GANADERA NORTE NEUQUINO | C5: =+'SERVICIO FAENA'!C5 -> 40 | D5: 562.14 | E5: 59.08 | L5: =+K5*F5 -> 0 | O5: =+K5*F5 -> 0 | P5: =+(L5*10.5/100)+L5 -> 0 | R5: 0 | S5: =+R5-P5 -> 0
A6: =+'SERVICIO FAENA'!A6 -> 4 | B6: =+'SERVICIO FAENA'!B6 -> DOS DE FIERRO SA | C6: =+'SERVICIO FAENA'!C6 -> 25 | D6: 403.98 | E6: 5.9 | L6: =+K6*F6 -> 0 | O6: =+K6*F6 -> 0 | P6: =+(L6*10.5/100)+L6 -> 0 | R6: 0 | S6: =+R6-P6 -> 0
A7: =+'SERVICIO FAENA'!A7 -> 5 | B7: =+'SERVICIO FAENA'!B7 -> DISTRIBUIDORA DE LA PATAGONIA | C7: =+'SERVICIO FAENA'!C7 -> 30 | D7: 450.62 | E7: 49.86 | L7: =+K7*F7 -> 0 | O7: =+K7*F7 -> 0 | P7: =+(L7*10.5/100)+L7 -> 0 | R7: 0 | S7: =+R7-P7 -> 0
A8: =+'SERVICIO FAENA'!A8 -> 6 | B8: =+'SERVICIO FAENA'!B8 -> DISTRIBUIDORA DE LA PATAGONIA | C8: =+'SERVICIO FAENA'!C8 -> 15 | D8: 214.99 | E8: 4.58 | L8: =+K8*F8 -> 0 | O8: =+K8*F8 -> 0 | P8: =+(L8*10.5/100)+L8 -> 0 | R8: 0 | S8: =+R8-P8 -> 0
A9: =+'SERVICIO FAENA'!A9 -> 7 | B9: =+'SERVICIO FAENA'!B9 -> MUCA SAS | C9: =+'SERVICIO FAENA'!C9 -> 35 | D9: 998.84 | E9: 15.84 | L9: =+K9*F9 -> 0 | O9: =+K9*F9 -> 0 | P9: =+(L9*10.5/100)+L9 -> 0 | R9: 0 | S9: =+R9-P9 -> 0
A10: =+'SERVICIO FAENA'!A10 -> 8 | B10: =+'SERVICIO FAENA'!B10 -> MUCA SAS | C10: =+'SERVICIO FAENA'!C10 -> 5 | L10: =+K10*F10 -> 0 | O10: =+K10*F10 -> 0 | P10: =+(L10*10.5/100)+L10 -> 0 | R10: 0 | S10: =+R10-P10 -> 0
A11: =+'SERVICIO FAENA'!A11 -> 9 | B11: =+'SERVICIO FAENA'!B11 -> MUCA SAS | C11: =+'SERVICIO FAENA'!C11 -> 10 | L11: =+K11*F11 -> 0 | O11: =+K11*F11 -> 0 | P11: =+(L11*10.5/100)+L11 -> 0 | R11: 0 | S11: =+R11-P11 -> 0
A12: =+'SERVICIO FAENA'!A12 -> 10 | B12: =+'SERVICIO FAENA'!B12 -> MORAGA | C12: =+'SERVICIO FAENA'!C12 -> 15 | D12: 243.74 | E12: 11.26 | L12: =+K12*F12 -> 0 | O12: =+K12*F12 -> 0 | P12: =+(L12*10.5/100)+L12 -> 0 | R12: 0 | S12: =+R12-P12 -> 0
A13: =+'SERVICIO FAENA'!A13 -> 11 | B13: =+'SERVICIO FAENA'!B13 -> FERREYRA MARTIN | C13: =+'SERVICIO FAENA'!C13 -> 20 | D13: 285.5 | E13: 23.78 | L13: =+K13*F13 -> 0 | O13: =+K13*F13 -> 0 | P13: =+(L13*10.5/100)+L13 -> 0 | R13: 0 | S13: =+R13-P13 -> 0
A14: =+'SERVICIO FAENA'!A14 -> 12 | B14: =+'SERVICIO FAENA'!B14 -> FERREYRA MARTIN | C14: =+'SERVICIO FAENA'!C14 -> 3 | L14: =+K14*F14 -> 0 | O14: =+K14*F14 -> 0 | P14: =+(L14*10.5/100)+L14 -> 0 | R14: 0 | S14: =+R14-P14 -> 0
A15: =+'SERVICIO FAENA'!A15 -> 13 | B15: =+'SERVICIO FAENA'!B15 -> GANADERA NORTE NEUQUINO | C15: =+'SERVICIO FAENA'!C15 -> 40 | D15: 680.64 | E15: 43.88 | L15: =+K15*F15 -> 0 | O15: =+K15*F15 -> 0 | P15: =+(L15*10.5/100)+L15 -> 0 | R15: 0 | S15: =+R15-P15 -> 0
A16: =+'SERVICIO FAENA'!A16 -> 14 | B16: =+'SERVICIO FAENA'!B16 -> FRIGORIFICO DE LA PATAGONIA SRL | C16: =+'SERVICIO FAENA'!C16 -> 35 | D16: 475.76 | L16: =+K16*F16 -> 0 | O16: =+K16*F16 -> 0 | P16: =+(L16*10.5/100)+L16 -> 0 | R16: 0 | S16: =+R16-P16 -> 0
A17: =+'SERVICIO FAENA'!A17 -> 15 | B17: =+'SERVICIO FAENA'!B17 -> GANADERA NORTE NEUQUINO | C17: =+'SERVICIO FAENA'!C17 -> 46 | D17: 680.32 | E17: 7.34 | L17: =+K17*F17 -> 0 | O17: =+K17*F17 -> 0 | P17: =+(L17*10.5/100)+L17 -> 0 | R17: 0 | S17: =+R17-P17 -> 0
A18: =+'SERVICIO FAENA'!A18 -> 16 | B18: =+'SERVICIO FAENA'!B18 -> MORAGA | C18: =+'SERVICIO FAENA'!C18 -> 15 | D18: 262.52 | L18: =+K18*F18 -> 0 | O18: =+K18*F18 -> 0 | P18: =+(L18*10.5/100)+L18 -> 0 | R18: 0 | S18: =+R18-P18 -> 0
A19: =+'SERVICIO FAENA'!A19 -> 17 | B19: =+'SERVICIO FAENA'!B19 -> LASAGNO JORGE ALBERTO | C19: =+'SERVICIO FAENA'!C19 -> 17 | D19: 278.78 | E19: 4.34 | L19: =+K19*F19 -> 0 | O19: =+K19*F19 -> 0 | P19: =+(L19*10.5/100)+L19 -> 0 | R19: 0 | S19: =+R19-P19 -> 0
A20: =+'SERVICIO FAENA'!A20 -> 18 | B20: =+'SERVICIO FAENA'!B20 -> GANADERA NORTE NEUQUINO | C20: =+'SERVICIO FAENA'!C20 -> 43 | D20: 640.84 | E20: 8.82 | L20: =+K20*F20 -> 0 | O20: =+K20*F20 -> 0 | P20: =+(L20*10.5/100)+L20 -> 0 | R20: 0 | S20: =+R20-P20 -> 0
A21: =+'SERVICIO FAENA'!A21 -> 19 | B21: =+'SERVICIO FAENA'!B21 -> DOS DE FIERRO SA | C21: =+'SERVICIO FAENA'!C21 -> 25 | D21: 230.52 | E21: 4.64 | L21: =+K21*F21 -> 0 | O21: =+K21*F21 -> 0 | P21: =+(L21*10.5/100)+L21 -> 0 | R21: 0 | S21: =+R21-P21 -> 0
A22: =+'SERVICIO FAENA'!A22 -> 20 | B22: =+'SERVICIO FAENA'!B22 -> FERREYRA MARTIN | C22: =+'SERVICIO FAENA'!C22 -> 15 | D22: 374.6 | L22: =+K22*F22 -> 0 | O22: =+K22*F22 -> 0 | P22: =+(L22*10.5/100)+L22 -> 0 | R22: 0 | S22: =+R22-P22 -> 0
A23: =+'SERVICIO FAENA'!A23 -> 21 | B23: =+'SERVICIO FAENA'!B23 -> MUCA SAS | C23: =+'SERVICIO FAENA'!C23 -> 8 | D23: 402.22 | E23: 8.76 | L23: =+K23*F23 -> 0 | O23: =+K23*F23 -> 0 | P23: =+(L23*10.5/100)+L23 -> 0 | R23: 0 | S23: =+R23-P23 -> 0
A24: =+'SERVICIO FAENA'!A24 -> 22 | B24: =+'SERVICIO FAENA'!B24 -> MUCA SAS | C24: =+'SERVICIO FAENA'!C24 -> 7 | L24: =+K24*F24 -> 0 | O24: =+K24*F24 -> 0 | P24: =+(L24*10.5/100)+L24 -> 0 | R24: 0 | S24: =+R24-P24 -> 0
A25: =+'SERVICIO FAENA'!A25 -> 23 | B25: =+'SERVICIO FAENA'!B25 -> MUCA SAS | C25: =+'SERVICIO FAENA'!C25 -> 5 | L25: =+K25*F25 -> 0 | O25: =+K25*F25 -> 0 | P25: =+(L25*10.5/100)+L25 -> 0 | R25: 0 | S25: =+R25-P25 -> 0
A26: =+'SERVICIO FAENA'!A26 -> 24 | B26: =+'SERVICIO FAENA'!B26 -> FERREYRA MARTIN | C26: =+'SERVICIO FAENA'!C26 -> 30 | D26: 442.84 | E26: 20.28 | L26: =+K26*F26 -> 0 | O26: =+K26*F26 -> 0 | P26: =+(L26*10.5/100)+L26 -> 0 | R26: 0 | S26: =+R26-P26 -> 0
A27: =+'SERVICIO FAENA'!A27 -> 25 | B27: =+'SERVICIO FAENA'!B27 -> FERREYRA ALBERTO | C27: =+'SERVICIO FAENA'!C27 -> 6 | D27: 86.58 | E27: 4.98 | L27: =+K27*F27 -> 0 | O27: =+K27*F27 -> 0 | P27: =+(L27*10.5/100)+L27 -> 0 | R27: 0 | S27: =+R27-P27 -> 0
A28: =+'SERVICIO FAENA'!A28 -> 26 | B28: =+'SERVICIO FAENA'!B28 -> FRIGORIFICO DE LA PATAGONIA SRL | C28: =+'SERVICIO FAENA'!C28 -> 50 | D28: 831.32 | E28: 19.08 | L28: =+K28*F28 -> 0 | O28: =+K28*F28 -> 0 | P28: =+(L28*10.5/100)+L28 -> 0 | R28: 0 | S28: =+R28-P28 -> 0
A29: =+'SERVICIO FAENA'!A29 -> 27 | B29: =+'SERVICIO FAENA'!B29 -> GANADERA NORTE NEUQUINO | C29: =+'SERVICIO FAENA'!C29 -> 40 | D29: 669.82 | E29: 29.4 | L29: =+K29*F29 -> 0 | O29: =+K29*F29 -> 0 | P29: =+(L29*10.5/100)+L29 -> 0 | R29: 0 | S29: =+R29-P29 -> 0
A30: =+'SERVICIO FAENA'!A30 -> 28 | B30: =+'SERVICIO FAENA'!B30 -> DOS DE FIERRO SA | C30: =+'SERVICIO FAENA'!C30 -> 26 | D30: 417.6 | E30: 9.84 | L30: =+K30*F30 -> 0 | O30: =+K30*F30 -> 0 | P30: =+(L30*10.5/100)+L30 -> 0 | R30: 0 | S30: =+R30-P30 -> 0
A31: =+'SERVICIO FAENA'!A31 -> 29 | B31: =+'SERVICIO FAENA'!B31 -> FERREYRA MARTIN | C31: =+'SERVICIO FAENA'!C31 -> 15 | D31: 210.28 | E31: 19.62 | L31: =+K31*F31 -> 0 | O31: =+K31*F31 -> 0 | P31: =+(L31*10.5/100)+L31 -> 0 | R31: 0 | S31: =+R31-P31 -> 0
A32: =+'SERVICIO FAENA'!A32 -> 30 | B32: =+'SERVICIO FAENA'!B32 -> BOSQUES AMADOS SRL | C32: =+'SERVICIO FAENA'!C32 -> 18 | D32: 255.58 | E32: 13.22 | L32: =+K32*F32 -> 0 | O32: =+K32*F32 -> 0 | P32: =+(L32*10.5/100)+L32 -> 0 | R32: 0 | S32: =+R32-P32 -> 0
A33: =+'SERVICIO FAENA'!A33 -> 31 | B33: =+'SERVICIO FAENA'!B33 -> MUCA SAS | C33: =+'SERVICIO FAENA'!C33 -> 50 | D33: 911.38 | E33: 12.96 | L33: =+K33*F33 -> 0 | O33: =+K33*F33 -> 0 | P33: =+(L33*10.5/100)+L33 -> 0 | R33: 0 | S33: =+R33-P33 -> 0
A34: =+'SERVICIO FAENA'!A34 -> 32 | B34: =+'SERVICIO FAENA'!B34 -> FERREYRA ALBERTO | C34: =+'SERVICIO FAENA'!C34 -> 8 | D34: 115.54 | L34: =+K34*F34 -> 0 | O34: =+K34*F34 -> 0 | P34: =+(L34*10.5/100)+L34 -> 0 | R34: 0 | S34: =+R34-P34 -> 0
A35: =+'SERVICIO FAENA'!A35 -> 33 | B35: =+'SERVICIO FAENA'!B35 -> FERREYRA MARTIN | C35: =+'SERVICIO FAENA'!C35 -> 20 | D35: 276.88 | E35: 35.34 | L35: =+K35*F35 -> 0 | O35: =+K35*F35 -> 0 | P35: =+(L35*10.5/100)+L35 -> 0 | R35: 0 | S35: =+R35-P35 -> 0
A36: =+'SERVICIO FAENA'!A36 -> 34 | B36: =+'SERVICIO FAENA'!B36 -> FRIGORIFICO DE LA PATAGONIA SRL | C36: =+'SERVICIO FAENA'!C36 -> 15 | D36: 246.74 | L36: =+K36*F36 -> 0 | O36: =+K36*F36 -> 0 | P36: =+(L36*10.5/100)+L36 -> 0 | R36: 0 | S36: =+R36-P36 -> 0
A37: =+'SERVICIO FAENA'!A37 -> 35 | B37: =+'SERVICIO FAENA'!B37 -> MUCA SAS | C37: =+'SERVICIO FAENA'!C37 -> 13 | D37: 467 | E37: 43.28 | L37: =+K37*F37 -> 0 | O37: =+K37*F37 -> 0 | P37: =+(L37*10.5/100)+L37 -> 0 | R37: 0 | S37: =+R37-P37 -> 0
A38: =+'SERVICIO FAENA'!A38 -> 36 | B38: =+'SERVICIO FAENA'!B38 -> MUCA SAS | C38: =+'SERVICIO FAENA'!C38 -> 15 | L38: =+K38*F38 -> 0 | O38: =+K38*F38 -> 0 | P38: =+(L38*10.5/100)+L38 -> 0 | R38: 0 | S38: =+R38-P38 -> 0
A39: =+'SERVICIO FAENA'!A39 -> 37 | B39: =+'SERVICIO FAENA'!B39 -> FERREYRA MARTIN | C39: =+'SERVICIO FAENA'!C39 -> 15 | D39: 188.44 | E39: 4.8 | L39: =+K39*F39 -> 0 | O39: =+K39*F39 -> 0 | P39: =+(L39*10.5/100)+L39 -> 0 | R39: 0 | S39: =+R39-P39 -> 0
A40: =+'SERVICIO FAENA'!A40 -> 38 | B40: =+'SERVICIO FAENA'!B40 -> FRIGORIFICO DE LA PATAGONIA SRL | C40: =+'SERVICIO FAENA'!C40 -> 26 | D40: 435.16 | E40: 10.1 | L40: =+K40*F40 -> 0 | O40: =+K40*F40 -> 0 | P40: =+(L40*10.5/100)+L40 -> 0 | R40: 0 | S40: =+R40-P40 -> 0
...

Sheet RENDERING
